Workbook

Sheet SETTINGS
A1: ⚡ FOREX TRADING JOURNAL — SETTINGS
A2: Configure all global parameters. Blue cells = user input. Do NOT edit black formula cells.
A4: ACCOUNT SETTINGS
A5: Account Currency | B5: USD
A6: Starting Balance | B6: 50000
A7: Current Balance | B7: =B6 -> 50000
A8: Default Risk % | B8: 0.01
A9: Max Daily Loss % | B9: 0.03
A10: Max Drawdown % | B10: 0.1
A12: PIP / POINT VALUE REFERENCE (Standard Lot = 100,000 units)
A13: Market Type | B13: Instrument Example | C13: Pip Size | D13: Pip Value / Std Lot (USD) | E13: Notes
A14: Forex Non-JPY | B14: EUR/USD, GBP/USD | C14: 0.0001 | D14: 10 | E14: 1 pip = 0.0001; $10/pip on std lot
A15: Forex JPY | B15: USD/JPY, GBP/JPY | C15: 0.01 | D15: ≈$9.09 | E15: 1 pip = 0.01; value varies w/ USD/JPY rate
A16: Gold XAUUSD | B16: XAU/USD | C16: 0.01 | D16: 1 | E16: $1/pip on std lot; 1 lot = 100 oz
A17: Indices – US | B17: US30, SPX500 | C17: 1 | D17: 1 | E17: 1 pt = $1 per mini-lot typically
A18: Indices – UK | B18: UK100 | C18: 1 | D18: £1 | E18: Currency-adjusted by broker
A19: Crypto | B19: BTC/USD | C19: 1 | D19: 1 | E19: Varies by broker contract size
A22: DROPDOWN SOURCE LISTS (Named Ranges — used by TRADE_LOG validation)
A23: Strategies | B23: Timeframes | C23: Markets | D23: Sessions | E23: Results | F23: Directions | G23: Confluences
A24: Breakout | B24: M1 | C24: EUR/USD | D24: London | E24: Win | F24: Buy | G24: Trend
A25: Trend Follow | B25: M5 | C25: GBP/USD | D25: New York | E25: Loss | F25: Sell | G25: S/R Level
A26: Mean Reversion | B26: M15 | C26: USD/JPY | D26: Asian | E26: Breakeven | G26: Fibonacci
A27: Scalp | B27: M30 | C27: GBP/JPY | D27: London/NY Overlap | E27: Partial Win | G27: Volume
A28: News Trade | B28: H1 | C28: AUD/USD | D28: Asian/London Overlap | E28: Open | G28: News
A29: Support/Resistance | B29: H4 | C29: USD/CAD | G29: Divergence
A30: ICT/SMC | B30: D1 | C30: EUR/JPY | G30: MA Cross
A31: Price Action | B31: W1 | C31: XAU/USD | G31: Order Block
A32: Harmonic | B32: MN | C32: US30 | G32: Fair Value Gap
A33: Other | C33: SPX500 | G33: BOS/CHoCH
C34: NAS100
C35: UK100
C36: Other

Sheet TRADE_LOG
A1: 📊 TRADE LOG — Complete Trade Record
A2: IDENTIFICATION | E2: INSTRUMENT | H2: SETUP | K2: ENTRY & RISK | S2: PARTIAL EXITS | AC2: RESULTS | AJ2: ANALYTICS & NOTES
A3: Trade ID | B3: Date Opened | C3: Time Opened | D3: Date Closed | E3: Market/Pair | F3: Direction | G3: Session | H3: Strategy | I3: Timeframe | J3: Confluences | K3: Entry Price | L3: Stop Loss | M3: Take Profit 1 | N3: Take Profit 2 | O3: Risk % | P3: SL Pips | Q3: Risk $ | R3: Lot Size | S3: Exit 1 Price | T3: Exit 1 % | U3: Exit 1 P/L $ | V3: Exit 2 Price | W3: Exit 2 % | X3: Exit 2 P/L $ | Y3: Exit 3 Price | Z3: Exit 3 % | AA3: Exit 3 P/L $ | AB3: Final Exit Price | AC3: Final Exit % | AD3: Wt Avg Exit | AE3: Total P/L $ | AF3: RR Ratio | AG3: R-Multiple | AH3: Result | AI3: Trade Duration | AJ3: Pips P/L | AK3: Notes | AL3: Screenshot URL | AM3: Mistakes | AN3: Emotion Score | AO3: Running Balance
A4: =IF(B4="","",ROW()-3) -> 1 | B4: 45306 | C4: 08:30 | D4: 45306 | E4: EUR/USD | F4: Buy | G4: London | H4: Trend Follow | I4: H1 | J4: Trend,S/R Level | K4: 1.0852 | L4: 1.0832 | M4: 1.09 | N4: 1.095 | O4: 0.01 | P4: =IF(K4="","",IFERROR(ABS(K4-L4)/IF(ISNUMBER(SEARCH("JPY",E4)),0.01,IF(ISNUMBER(SEARCH("XAU",E4)),0.01,IF(OR(ISNUMBER(SEARCH("30",E4)),ISNUMBER(SEARCH("500",E4)),ISNUMBER(SEARCH("100",E4))),1,0.0001))),0)) -> 20 | Q4: =IF(K4="","",SETTINGS!$B$6*O4) -> 500 | R4: =IF(K4="","",IFERROR(Q4/(P4*IF(ISNUMBER(SEARCH("JPY",E4)),9.09,IF(ISNUMBER(SEARCH("XAU",E4)),1,IF(OR(ISNUMBER(SEARCH("30",E4)),ISNUMBER(SEARCH("500",E4)),ISNUMBER(SEARCH("100",E4))),1,10)))),0)) -> 2.5 | S4: 1.0885 | T4: 0.5 | U4: =IF(OR(S4="",T4=0),"",IFERROR((S4-K4)*IF(F4="Sell",-1,1)*R4*T4*IF(ISNUMBER(SEARCH("JPY",E4)),1000,IF(ISNUMBER(SEARCH("XAU",E4)),100,IF(OR(ISNUMBER(SEARCH("30",E4)),ISNUMBER(SEARCH("500",E4)),ISNUMBER(SEARCH("100",E4))),100,100000))),0)) -> 412.5 | X4: =IF(OR(V4="",W4=0),"",IFERROR((V4-K4)*IF(F4="Sell",-1,1)*R4*W4*IF(ISNUMBER(SEARCH("JPY",E4)),1000,IF(ISNUMBER(SEARCH("XAU",E4)),100,IF(OR(ISNUMBER(SEARCH("30",E4)),ISNUMBER(SEARCH("500",E4)),ISNUMBER(SEARCH("100",E4))),100,100000))),0)) | AA4: =IF(OR(Y4="",Z4=0),"",IFERROR((Y4-K4)*IF(F4="Sell",-1,1)*R4*Z4*IF(ISNUMBER(SEARCH("JPY",E4)),1000,IF(ISNUMBER(SEARCH("XAU",E4)),100,IF(OR(ISNUMBER(SEARCH("30",E4)),ISNUMBER(SEARCH("500",E4)),ISNUMBER(SEARCH("100",E4))),100,100000))),0)) | AB4: 1.091 | AC4: =IF(K4="","",1-IFERROR(T4,0)-IFERROR(W4,0)-IFERROR(Z4,0)) -> 0.5 | AD4: =IF(AB4="","",IFERROR((IFERROR(S4*T4,0)+IFERROR(V4*W4,0)+IFERROR(Y4*Z4,0)+AB4*AC4)/(IFERROR(T4,0)+IFERROR(W4,0)+IFERROR(Z4,0)+AC4),AB4)) -> 1.08975 | AE4: =IF(AB4="","",IF(U4="",0,U4)+IF(X4="",0,X4)+IF(AA4="",0,AA4)+IFERROR((AB4-K4)*IF(F4="Sell",-1,1)*R4*AC4*IF(ISNUMBER(SEARCH("JPY",E4)),1000,IF(ISNUMBER(SEARCH("XAU",E4)),100,IF(OR(ISNUMBER(SEARCH("30",E4)),ISNUMBER(SEARCH("500",E4)),ISNUMBER(SEARCH("100",E4))),100,100000))),0)) -> 1137.5 | AF4: =IF(OR(K4="",M4="",L4=""),"",IFERROR(ABS(M4-K4)/ABS(K4-L4),0)) -> 2.4 | AG4: =IF(OR(AE4="",AE4=0,Q4=0,Q4=""),"",IFERROR(AE4/Q4,0)) -> 2.275 | AH4: =IF(AB4="","Open",IF(AG4="","Open",IF(AG4>0.1,"Win",IF(AG4<-0.1,"Loss","Breakeven")))) -> Win | AI4: =IF(OR(B4="",D4=""),"",D4-B4) -> 0 | AJ4: =IF(AD4="","",IFERROR((AD4-K4)*IF(F4="Sell",-1,1)/IF(ISNUMBER(SEARCH("JPY",E4)),0.01,IF(ISNUMBER(SEARCH("XAU",E4)),0.01,IF(OR(ISNUMBER(SEARCH("30",E4)),ISNUMBER(SEARCH("500",E4)),ISNUMBER(SEARCH("100",E4))),1,0.0001))),0)) -> 45.5 | AK4: Clean breakout setup | AN4: 7 | AO4: =IF(AE4="","",SETTINGS!$B$6+IF(AE4="",0,AE4)) -> 51137.5
A5: =IF(B5="","",ROW()-3) -> 2 | B5: 45307 | C5: 10:15 | D5: 45307 | E5: GBP/USD | F5: Sell | G5: London/NY Overlap | H5: Price Action | I5: H4 | J5: S/R Level,BOS/CHoCH | K5: 1.2765 | L5: 1.2795 | M5: 1.271 | N5: 1.268 | O5: 0.01 | P5: =IF(K5="","",IFERROR(ABS(K5-L5)/IF(ISNUMBER(SEARCH("JPY",E5)),0.01,IF(ISNUMBER(SEARCH("XAU",E5)),0.01,IF(OR(ISNUMBER(SEARCH("30",E5)),ISNUMBER(SEARCH("500",E5)),ISNUMBER(SEARCH("100",E5))),1,0.0001))),0)) -> 30 | Q5: =IF(K5="","",SETTINGS!$B$6*O5) -> 500 | R5: =IF(K5="","",IFERROR(Q5/(P5*IF(ISNUMBER(SEARCH("JPY",E5)),9.09,IF(ISNUMBER(SEARCH("XAU",E5)),1,IF(OR(ISNUMBER(SEARCH("30",E5)),ISNUMBER(SEARCH("500",E5)),ISNUMBER(SEARCH("100",E5))),1,10)))),0)) -> 1.6666667 | T5: 0 | U5: =IF(OR(S5="",T5=0),"",IFERROR((S5-K5)*IF(F5="Sell",-1,1)*R5*T5*IF(ISNUMBER(SEARCH("JPY",E5)),1000,IF(ISNUMBER(SEARCH("XAU",E5)),100,IF(OR(ISNUMBER(SEARCH("30",E5)),ISNUMBER(SEARCH("500",E5)),ISNUMBER(SEARCH("100",E5))),100,100000))),0)) | X5: =IF(OR(V5="",W5=0),"",IFERROR((V5-K5)*IF(F5="Sell",-1,1)*R5*W5*IF(ISNUMBER(SEARCH("JPY",E5)),1000,IF(ISNUMBER(SEARCH("XAU",E5)),100,IF(OR(ISNUMBER(SEARCH("30",E5)),ISNUMBER(SEARCH("500",E5)),ISNUMBER(SEARCH("100",E5))),100,100000))),0)) | AA5: =IF(OR(Y5="",Z5=0),"",IFERROR((Y5-K5)*IF(F5="Sell",-1,1)*R5*Z5*IF(ISNUMBER(SEARCH("JPY",E5)),1000,IF(ISNUMBER(SEARCH("XAU",E5)),100,IF(OR(ISNUMBER(SEARCH("30",E5)),ISNUMBER(SEARCH("500",E5)),ISNUMBER(SEARCH("100",E5))),100,100000))),0)) | AB5: 1.271 | AC5: =IF(K5="","",1-IFERROR(T5,0)-IFERROR(W5,0)-IFERROR(Z5,0)) -> 1 | AD5: =IF(AB5="","",IFERROR((IFERROR(S5*T5,0)+IFERROR(V5*W5,0)+IFERROR(Y5*Z5,0)+AB5*AC5)/(IFERROR(T5,0)+IFERROR(W5,0)+IFERROR(Z5,0)+AC5),AB5)) -> 1.271 | AE5: =IF(AB5="","",IF(U5="",0,U5)+IF(X5="",0,X5)+IF(AA5="",0,AA5)+IFERROR((AB5-K5)*IF(F5="Sell",-1,1)*R5*AC5*IF(ISNUMBER(SEARCH("JPY",E5)),1000,IF(ISNUMBER(SEARCH("XAU",E5)),100,IF(OR(ISNUMBER(SEARCH("30",E5)),ISNUMBER(SEARCH("500",E5)),ISNUMBER(SEARCH("100",E5))),100,100000))),0)) -> 916.66667 | AF5: =IF(OR(K5="",M5="",L5=""),"",IFERROR(ABS(M5-K5)/ABS(K5-L5),0)) -> 1.8333333 | AG5: =IF(OR(AE5="",AE5=0,Q5=0,Q5=""),"",IFERROR(AE5/Q5,0)) -> 1.8333333 | AH5: =IF(AB5="","Open",IF(AG5="","Open",IF(AG5>0.1,"Win",IF(AG5<-0.1,"Loss","Breakeven")))) -> Win | AI5: =IF(OR(B5="",D5=""),"",D5-B5) -> 0 | AJ5: =IF(AD5="","",IFERROR((AD5-K5)*IF(F5="Sell",-1,1)/IF(ISNUMBER(SEARCH("JPY",E5)),0.01,IF(ISNUMBER(SEARCH("XAU",E5)),0.01,IF(OR(ISNUMBER(SEARCH("30",E5)),ISNUMBER(SEARCH("500",E5)),ISNUMBER(SEARCH("100",E5))),1,0.0001))),0)) -> 55 | AK5: Double top rejection | AN5: 6 | AO5: =IF(AE5="","",IFERROR(IF(AO4="",SETTINGS!$B$6,AO4),SETTINGS!$B$6)+IF(AE5="",0,AE5)) -> 52054.167
A6: =IF(B6="","",ROW()-3) -> 3 | B6: 45308 | C6: 14:00 | D6: 45309 | E6: XAU/USD | F6: Buy | G6: New York | H6: Breakout | I6: H1 | J6: Trend,Volume | K6: 2025.5 | L6: 2018 | M6: 2040 | N6: 2055 | O6: 0.015 | P6: =IF(K6="","",IFERROR(ABS(K6-L6)/IF(ISNUMBER(SEARCH("JPY",E6)),0.01,IF(ISNUMBER(SEARCH("XAU",E6)),0.01,IF(OR(ISNUMBER(SEARCH("30",E6)),ISNUMBER(SEARCH("500",E6)),ISNUMBER(SEARCH("100",E6))),1,0.0001))),0)) -> 750 | Q6: =IF(K6="","",SETTINGS!$B$6*O6) -> 750 | R6: =IF(K6="","",IFERROR(Q6/(P6*IF(ISNUMBER(SEARCH("JPY",E6)),9.09,IF(ISNUMBER(SEARCH("XAU",E6)),1,IF(OR(ISNUMBER(SEARCH("30",E6)),ISNUMBER(SEARCH("500",E6)),ISNUMBER(SEARCH("100",E6))),1,10)))),0)) -> 1 | S6: 2038 | T6: 0.4 | U6: =IF(OR(S6="",T6=0),"",IFERROR((S6-K6)*IF(F6="Sell",-1,1)*R6*T6*IF(ISNUMBER(SEARCH("JPY",E6)),1000,IF(ISNUMBER(SEARCH("XAU",E6)),100,IF(OR(ISNUMBER(SEARCH("30",E6)),ISNUMBER(SEARCH("500",E6)),ISNUMBER(SEARCH("100",E6))),100,100000))),0)) -> 500 | V6: 2045 | W6: 0.35 | X6: =IF(OR(V6="",W6=0),"",IFERROR((V6-K6)*IF(F6="Sell",-1,1)*R6*W6*IF(ISNUMBER(SEARCH("JPY",E6)),1000,IF(ISNUMBER(SEARCH("XAU",E6)),100,IF(OR(ISNUMBER(SEARCH("30",E6)),ISNUMBER(SEARCH("500",E6)),ISNUMBER(SEARCH("100",E6))),100,100000))),0)) -> 682.5 | AA6: =IF(OR(Y6="",Z6=0),"",IFERROR((Y6-K6)*IF(F6="Sell",-1,1)*R6*Z6*IF(ISNUMBER(SEARCH("JPY",E6)),1000,IF(ISNUMBER(SEARCH("XAU",E6)),100,IF(OR(ISNUMBER(SEARCH("30",E6)),ISNUMBER(SEARCH("500",E6)),ISNUMBER(SEARCH("100",E6))),100,100000))),0)) | AB6: 2050 | AC6: =IF(K6="","",1-IFERROR(T6,0)-IFERROR(W6,0)-IFERROR(Z6,0)) -> 0.25 | AD6: =IF(AB6="","",IFERROR((IFERROR(S6*T6,0)+IFERROR(V6*W6,0)+IFERROR(Y6*Z6,0)+AB6*AC6)/(IFERROR(T6,0)+IFERROR(W6,0)+IFERROR(Z6,0)+AC6),AB6)) -> 2043.45 | AE6: =IF(AB6="","",IF(U6="",0,U6)+IF(X6="",0,X6)+IF(AA6="",0,AA6)+IFERROR((AB6-K6)*IF(F6="Sell",-1,1)*R6*AC6*IF(ISNUMBER(SEARCH("JPY",E6)),1000,IF(ISNUMBER(SEARCH("XAU",E6)),100,IF(OR(ISNUMBER(SEARCH("30",E6)),ISNUMBER(SEARCH("500",E6)),ISNUMBER(SEARCH("100",E6))),100,100000))),0)) -> 1795 | AF6: =IF(OR(K6="",M6="",L6=""),"",IFERROR(ABS(M6-K6)/ABS(K6-L6),0)) -> 1.9333333 | AG6: =IF(OR(AE6="",AE6=0,Q6=0,Q6=""),"",IFERROR(AE6/Q6,0)) -> 2.3933333 | AH6: =IF(AB6="","Open",IF(AG6="","Open",IF(AG6>0.1,"Win",IF(AG6<-0.1,"Loss","Breakeven")))) -> Win | AI6: =IF(OR(B6="",D6=""),"",D6-B6) -> 1 | AJ6: =IF(AD6="","",IFERROR((AD6-K6)*IF(F6="Sell",-1,1)/IF(ISNUMBER(SEARCH("JPY",E6)),0.01,IF(ISNUMBER(SEARCH("XAU",E6)),0.01,IF(OR(ISNUMBER(SEARCH("30",E6)),ISNUMBER(SEARCH("500",E6)),ISNUMBER(SEARCH("100",E6))),1,0.0001))),0)) -> 1795 | AK6: Gold trending strongly | AN6: 8 | AO6: =IF(AE6="","",IFERROR(IF(AO5="",SETTINGS!$B$6,AO5),SETTINGS!$B$6)+IF(AE6="",0,AE6)) -> 53849.167
A7: =IF(B7="","",ROW()-3) -> 4 | B7: 45309 | C7: 09:00 | D7: 45309 | E7: USD/JPY | F7: Sell | G7: Asian | H7: Mean Reversion | I7: M15 | J7: S/R Level,Divergence | K7: 148.25 | L7: 148.65 | M7: 147.5 | O7: 0.01 | P7: =IF(K7="","",IFERROR(ABS(K7-L7)/IF(ISNUMBER(SEARCH("JPY",E7)),0.01,IF(ISNUMBER(SEARCH("XAU",E7)),0.01,IF(OR(ISNUMBER(SEARCH("30",E7)),ISNUMBER(SEARCH("500",E7)),ISNUMBER(SEARCH("100",E7))),1,0.0001))),0)) -> 40 | Q7: =IF(K7="","",SETTINGS!$B$6*O7) -> 500 | R7: =IF(K7="","",IFERROR(Q7/(P7*IF(ISNUMBER(SEARCH("JPY",E7)),9.09,IF(ISNUMBER(SEARCH("XAU",E7)),1,IF(OR(ISNUMBER(SEARCH("30",E7)),ISNUMBER(SEARCH("500",E7)),ISNUMBER(SEARCH("100",E7))),1,10)))),0)) -> 1.3751375 | T7: 0 | U7: =IF(OR(S7="",T7=0),"",IFERROR((S7-K7)*IF(F7="Sell",-1,1)*R7*T7*IF(ISNUMBER(SEARCH("JPY",E7)),1000,IF(ISNUMBER(SEARCH("XAU",E7)),100,IF(OR(ISNUMBER(SEARCH("30",E7)),ISNUMBER(SEARCH("500",E7)),ISNUMBER(SEARCH("100",E7))),100,100000))),0)) | X7: =IF(OR(V7="",W7=0),"",IFERROR((V7-K7)*IF(F7="Sell",-1,1)*R7*W7*IF(ISNUMBER(SEARCH("JPY",E7)),1000,IF(ISNUMBER(SEARCH("XAU",E7)),100,IF(OR(ISNUMBER(SEARCH("30",E7)),ISNUMBER(SEARCH("500",E7)),ISNUMBER(SEARCH("100",E7))),100,100000))),0)) | AA7: =IF(OR(Y7="",Z7=0),"",IFERROR((Y7-K7)*IF(F7="Sell",-1,1)*R7*Z7*IF(ISNUMBER(SEARCH("JPY",E7)),1000,IF(ISNUMBER(SEARCH("XAU",E7)),100,IF(OR(ISNUMBER(SEARCH("30",E7)),ISNUMBER(SEARCH("500",E7)),ISNUMBER(SEARCH("100",E7))),100,100000))),0)) | AB7: 147.8 | AC7: =IF(K7="","",1-IFERROR(T7,0)-IFERROR(W7,0)-IFERROR(Z7,0)) -> 1 | AD7: =IF(AB7="","",IFERROR((IFERROR(S7*T7,0)+IFERROR(V7*W7,0)+IFERROR(Y7*Z7,0)+AB7*AC7)/(IFERROR(T7,0)+IFERROR(W7,0)+IFERROR(Z7,0)+AC7),AB7)) -> 147.8 | AE7: =IF(AB7="","",IF(U7="",0,U7)+IF(X7="",0,X7)+IF(AA7="",0,AA7)+IFERROR((AB7-K7)*IF(F7="Sell",-1,1)*R7*AC7*IF(ISNUMBER(SEARCH("JPY",E7)),1000,IF(ISNUMBER(SEARCH("XAU",E7)),100,IF(OR(ISNUMBER(SEARCH("30",E7)),ISNUMBER(SEARCH("500",E7)),ISNUMBER(SEARCH("100",E7))),100,100000))),0)) -> 618.81188 | AF7: =IF(OR(K7="",M7="",L7=""),"",IFERROR(ABS(M7-K7)/ABS(K7-L7),0)) -> 1.875 | AG7: =IF(OR(AE7="",AE7=0,Q7=0,Q7=""),"",IFERROR(AE7/Q7,0)) -> 1.2376238 | AH7: =IF(AB7="","Open",IF(AG7="","Open",IF(AG7>0.1,"Win",IF(AG7<-0.1,"Loss","Breakeven")))) -> Win | AI7: =IF(OR(B7="",D7=""),"",D7-B7) -> 0 | AJ7: =IF(AD7="","",IFERROR((AD7-K7)*IF(F7="Sell",-1,1)/IF(ISNUMBER(SEARCH("JPY",E7)),0.01,IF(ISNUMBER(SEARCH("XAU",E7)),0.01,IF(OR(ISNUMBER(SEARCH("30",E7)),ISNUMBER(SEARCH("500",E7)),ISNUMBER(SEARCH("100",E7))),1,0.0001))),0)) -> 45 | AK7: Quick scalp at resistance | AN7: 5 | AO7: =IF(AE7="","",IFERROR(IF(AO6="",SETTINGS!$B$6,AO6),SETTINGS!$B$6)+IF(AE7="",0,AE7)) -> 54467.979
A8: =IF(B8="","",ROW()-3) -> 5 | B8: 45313 | C8: 08:45 | D8: 45313 | E8: EUR/USD | F8: Buy | G8: London | H8: ICT/SMC | I8: H1 | J8: Order Block,Fair Value Gap | K8: 1.0879 | L8: 1.0859 | M8: 1.092 | O8: 0.01 | P8: =IF(K8="","",IFERROR(ABS(K8-L8)/IF(ISNUMBER(SEARCH("JPY",E8)),0.01,IF(ISNUMBER(SEARCH("XAU",E8)),0.01,IF(OR(ISNUMBER(SEARCH("30",E8)),ISNUMBER(SEARCH("500",E8)),ISNUMBER(SEARCH("100",E8))),1,0.0001))),0)) -> 20 | Q8: =IF(K8="","",SETTINGS!$B$6*O8) -> 500 | R8: =IF(K8="","",IFERROR(Q8/(P8*IF(ISNUMBER(SEARCH("JPY",E8)),9.09,IF(ISNUMBER(SEARCH("XAU",E8)),1,IF(OR(ISNUMBER(SEARCH("30",E8)),ISNUMBER(SEARCH("500",E8)),ISNUMBER(SEARCH("100",E8))),1,10)))),0)) -> 2.5 | S8: 1.0905 | T8: 0.6 | U8: =IF(OR(S8="",T8=0),"",IFERROR((S8-K8)*IF(F8="Sell",-1,1)*R8*T8*IF(ISNUMBER(SEARCH("JPY",E8)),1000,IF(ISNUMBER(SEARCH("XAU",E8)),100,IF(OR(ISNUMBER(SEARCH("30",E8)),ISNUMBER(SEARCH("500",E8)),ISNUMBER(SEARCH("100",E8))),100,100000))),0)) -> 390 | X8: =IF(OR(V8="",W8=0),"",IFERROR((V8-K8)*IF(F8="Sell",-1,1)*R8*W8*IF(ISNUMBER(SEARCH("JPY",E8)),1000,IF(ISNUMBER(SEARCH("XAU",E8)),100,IF(OR(ISNUMBER(SEARCH("30",E8)),ISNUMBER(SEARCH("500",E8)),ISNUMBER(SEARCH("100",E8))),100,100000))),0)) | AA8: =IF(OR(Y8="",Z8=0),"",IFERROR((Y8-K8)*IF(F8="Sell",-1,1)*R8*Z8*IF(ISNUMBER(SEARCH("JPY",E8)),1000,IF(ISNUMBER(SEARCH("XAU",E8)),100,IF(OR(ISNUMBER(SEARCH("30",E8)),ISNUMBER(SEARCH("500",E8)),ISNUMBER(SEARCH("100",E8))),100,100000))),0)) | AB8: 1.0915 | AC8: =IF(K8="","",1-IFERROR(T8,0)-IFERROR(W8,0)-IFERROR(Z8,0)) -> 0.4 | AD8: =IF(AB8="","",IFERROR((IFERROR(S8*T8,0)+IFERROR(V8*W8,0)+IFERROR(Y8*Z8,0)+AB8*AC8)/(IFERROR(T8,0)+IFERROR(W8,0)+IFERROR(Z8,0)+AC8),AB8)) -> 1.0909 | AE8: =IF(AB8="","",IF(U8="",0,U8)+IF(X8="",0,X8)+IF(AA8="",0,AA8)+IFERROR((AB8-K8)*IF(F8="Sell",-1,1)*R8*AC8*IF(ISNUMBER(SEARCH("JPY",E8)),1000,IF(ISNUMBER(SEARCH("XAU",E8)),100,IF(OR(ISNUMBER(SEARCH("30",E8)),ISNUMBER(SEARCH("500",E8)),ISNUMBER(SEARCH("100",E8))),100,100000))),0)) -> 750 | AF8: =IF(OR(K8="",M8="",L8=""),"",IFERROR(ABS(M8-K8)/ABS(K8-L8),0)) -> 2.05 | AG8: =IF(OR(AE8="",AE8=0,Q8=0,Q8=""),"",IFERROR(AE8/Q8,0)) -> 1.5 | AH8: =IF(AB8="","Open",IF(AG8="","Open",IF(AG8>0.1,"Win",IF(AG8<-0.1,"Loss","Breakeven")))) -> Win | AI8: =IF(OR(B8="",D8=""),"",D8-B8) -> 0 | AJ8: =IF(AD8="","",IFERROR((AD8-K8)*IF(F8="Sell",-1,1)/IF(ISNUMBER(SEARCH("JPY",E8)),0.01,IF(ISNUMBER(SEARCH("XAU",E8)),0.01,IF(OR(ISNUMBER(SEARCH("30",E8)),ISNUMBER(SEARCH("500",E8)),ISNUMBER(SEARCH("100",E8))),1,0.0001))),0)) -> 30 | AK8: FVG entry off London open | AN8: 9 | AO8: =IF(AE8="","",IFERROR(IF(AO7="",SETTINGS!$B$6,AO7),SETTINGS!$B$6)+IF(AE8="",0,AE8)) -> 55217.979
A9: =IF(B9="","",ROW()-3) | P9: =IF(K9="","",IFERROR(ABS(K9-L9)/IF(ISNUMBER(SEARCH("JPY",E9)),0.01,IF(ISNUMBER(SEARCH("XAU",E9)),0.01,IF(OR(ISNUMBER(SEARCH("30",E9)),ISNUMBER(SEARCH("500",E9)),ISNUMBER(SEARCH("100",E9))),1,0.0001))),0)) | Q9: =IF(K9="","",SETTINGS!$B$6*O9) | R9: =IF(K9="","",IFERROR(Q9/(P9*IF(ISNUMBER(SEARCH("JPY",E9)),9.09,IF(ISNUMBER(SEARCH("XAU",E9)),1,IF(OR(ISNUMBER(SEARCH("30",E9)),ISNUMBER(SEARCH("500",E9)),ISNUMBER(SEARCH("100",E9))),1,10)))),0)) | U9: =IF(OR(S9="",T9=0),"",IFERROR((S9-K9)*IF(F9="Sell",-1,1)*R9*T9*IF(ISNUMBER(SEARCH("JPY",E9)),1000,IF(ISNUMBER(SEARCH("XAU",E9)),100,IF(OR(ISNUMBER(SEARCH("30",E9)),ISNUMBER(SEARCH("500",E9)),ISNUMBER(SEARCH("100",E9))),100,100000))),0)) | X9: =IF(OR(V9="",W9=0),"",IFERROR((V9-K9)*IF(F9="Sell",-1,1)*R9*W9*IF(ISNUMBER(SEARCH("JPY",E9)),1000,IF(ISNUMBER(SEARCH("XAU",E9)),100,IF(OR(ISNUMBER(SEARCH("30",E9)),ISNUMBER(SEARCH("500",E9)),ISNUMBER(SEARCH("100",E9))),100,100000))),0)) | AA9: =IF(OR(Y9="",Z9=0),"",IFERROR((Y9-K9)*IF(F9="Sell",-1,1)*R9*Z9*IF(ISNUMBER(SEARCH("JPY",E9)),1000,IF(ISNUMBER(SEARCH("XAU",E9)),100,IF(OR(ISNUMBER(SEARCH("30",E9)),ISNUMBER(SEARCH("500",E9)),ISNUMBER(SEARCH("100",E9))),100,100000))),0)) | AC9: =IF(K9="","",1-IFERROR(T9,0)-IFERROR(W9,0)-IFERROR(Z9,0)) | AD9: =IF(AB9="","",IFERROR((IFERROR(S9*T9,0)+IFERROR(V9*W9,0)+IFERROR(Y9*Z9,0)+AB9*AC9)/(IFERROR(T9,0)+IFERROR(W9,0)+IFERROR(Z9,0)+AC9),AB9)) | AE9: =IF(AB9="","",IF(U9="",0,U9)+IF(X9="",0,X9)+IF(AA9="",0,AA9)+IFERROR((AB9-K9)*IF(F9="Sell",-1,1)*R9*AC9*IF(ISNUMBER(SEARCH("JPY",E9)),1000,IF(ISNUMBER(SEARCH("XAU",E9)),100,IF(OR(ISNUMBER(SEARCH("30",E9)),ISNUMBER(SEARCH("500",E9)),ISNUMBER(SEARCH("100",E9))),100,100000))),0)) | AF9: =IF(OR(K9="",M9="",L9=""),"",IFERROR(ABS(M9-K9)/ABS(K9-L9),0)) | AG9: =IF(OR(AE9="",AE9=0,Q9=0,Q9=""),"",IFERROR(AE9/Q9,0)) | AH9: =IF(AB9="","Open",IF(AG9="","Open",IF(AG9>0.1,"Win",IF(AG9<-0.1,"Loss","Breakeven")))) -> Open | AI9: =IF(OR(B9="",D9=""),"",D9-B9) | AJ9: =IF(AD9="","",IFERROR((AD9-K9)*IF(F9="Sell",-1,1)/IF(ISNUMBER(SEARCH("JPY",E9)),0.01,IF(ISNUMBER(SEARCH("XAU",E9)),0.01,IF(OR(ISNUMBER(SEARCH("30",E9)),ISNUMBER(SEARCH("500",E9)),ISNUMBER(SEARCH("100",E9))),1,0.0001))),0)) | AO9: =IF(AE9="","",IFERROR(IF(AO8="",SETTINGS!$B$6,AO8),SETTINGS!$B$6)+IF(AE9="",0,AE9))
A10: =IF(B10="","",ROW()-3) | P10: =IF(K10="","",IFERROR(ABS(K10-L10)/IF(ISNUMBER(SEARCH("JPY",E10)),0.01,IF(ISNUMBER(SEARCH("XAU",E10)),0.01,IF(OR(ISNUMBER(SEARCH("30",E10)),ISNUMBER(SEARCH("500",E10)),ISNUMBER(SEARCH("100",E10))),1,0.0001))),0)) | Q10: =IF(K10="","",SETTINGS!$B$6*O10) | R10: =IF(K10="","",IFERROR(Q10/(P10*IF(ISNUMBER(SEARCH("JPY",E10)),9.09,IF(ISNUMBER(SEARCH("XAU",E10)),1,IF(OR(ISNUMBER(SEARCH("30",E10)),ISNUMBER(SEARCH("500",E10)),ISNUMBER(SEARCH("100",E10))),1,10)))),0)) | U10: =IF(OR(S10="",T10=0),"",IFERROR((S10-K10)*IF(F10="Sell",-1,1)*R10*T10*IF(ISNUMBER(SEARCH("JPY",E10)),1000,IF(ISNUMBER(SEARCH("XAU",E10)),100,IF(OR(ISNUMBER(SEARCH("30",E10)),ISNUMBER(SEARCH("500",E10)),ISNUMBER(SEARCH("100",E10))),100,100000))),0)) | X10: =IF(OR(V10="",W10=0),"",IFERROR((V10-K10)*IF(F10="Sell",-1,1)*R10*W10*IF(ISNUMBER(SEARCH("JPY",E10)),1000,IF(ISNUMBER(SEARCH("XAU",E10)),100,IF(OR(ISNUMBER(SEARCH("30",E10)),ISNUMBER(SEARCH("500",E10)),ISNUMBER(SEARCH("100",E10))),100,100000))),0)) | AA10: =IF(OR(Y10="",Z10=0),"",IFERROR((Y10-K10)*IF(F10="Sell",-1,1)*R10*Z10*IF(ISNUMBER(SEARCH("JPY",E10)),1000,IF(ISNUMBER(SEARCH("XAU",E10)),100,IF(OR(ISNUMBER(SEARCH("30",E10)),ISNUMBER(SEARCH("500",E10)),ISNUMBER(SEARCH("100",E10))),100,100000))),0)) | AC10: =IF(K10="","",1-IFERROR(T10,0)-IFERROR(W10,0)-IFERROR(Z10,0)) | AD10: =IF(AB10="","",IFERROR((IFERROR(S10*T10,0)+IFERROR(V10*W10,0)+IFERROR(Y10*Z10,0)+AB10*AC10)/(IFERROR(T10,0)+IFERROR(W10,0)+IFERROR(Z10,0)+AC10),AB10)) | AE10: =IF(AB10="","",IF(U10="",0,U10)+IF(X10="",0,X10)+IF(AA10="",0,AA10)+IFERROR((AB10-K10)*IF(F10="Sell",-1,1)*R10*AC10*IF(ISNUMBER(SEARCH("JPY",E10)),1000,IF(ISNUMBER(SEARCH("XAU",E10)),100,IF(OR(ISNUMBER(SEARCH("30",E10)),ISNUMBER(SEARCH("500",E10)),ISNUMBER(SEARCH("100",E10))),100,100000))),0)) | AF10: =IF(OR(K10="",M10="",L10=""),"",IFERROR(ABS(M10-K10)/ABS(K10-L10),0)) | AG10: =IF(OR(AE10="",AE10=0,Q10=0,Q10=""),"",IFERROR(AE10/Q10,0)) | AH10: =IF(AB10="","Open",IF(AG10="","Open",IF(AG10>0.1,"Win",IF(AG10<-0.1,"Loss","Breakeven")))) -> Open | AI10: =IF(OR(B10="",D10=""),"",D10-B10) | AJ10: =IF(AD10="","",IFERROR((AD10-K10)*IF(F10="Sell",-1,1)/IF(ISNUMBER(SEARCH("JPY",E10)),0.01,IF(ISNUMBER(SEARCH("XAU",E10)),0.01,IF(OR(ISNUMBER(SEARCH("30",E10)),ISNUMBER(SEARCH("500",E10)),ISNUMBER(SEARCH("100",E10))),1,0.0001))),0)) | AO10: =IF(AE10="","",IFERROR(IF(AO9="",SETTINGS!$B$6,AO9),SETTINGS!$B$6)+IF(AE10="",0,AE10))
A11: =IF(B11="","",ROW()-3) | P11: =IF(K11="","",IFERROR(ABS(K11-L11)/IF(ISNUMBER(SEARCH("JPY",E11)),0.01,IF(ISNUMBER(SEARCH("XAU",E11)),0.01,IF(OR(ISNUMBER(SEARCH("30",E11)),ISNUMBER(SEARCH("500",E11)),ISNUMBER(SEARCH("100",E11))),1,0.0001))),0)) | Q11: =IF(K11="","",SETTINGS!$B$6*O11) | R11: =IF(K11="","",IFERROR(Q11/(P11*IF(ISNUMBER(SEARCH("JPY",E11)),9.09,IF(ISNUMBER(SEARCH("XAU",E11)),1,IF(OR(ISNUMBER(SEARCH("30",E11)),ISNUMBER(SEARCH("500",E11)),ISNUMBER(SEARCH("100",E11))),1,10)))),0)) | U11: =IF(OR(S11="",T11=0),"",IFERROR((S11-K11)*IF(F11="Sell",-1,1)*R11*T11*IF(ISNUMBER(SEARCH("JPY",E11)),1000,IF(ISNUMBER(SEARCH("XAU",E11)),100,IF(OR(ISNUMBER(SEARCH("30",E11)),ISNUMBER(SEARCH("500",E11)),ISNUMBER(SEARCH("100",E11))),100,100000))),0)) | X11: =IF(OR(V11="",W11=0),"",IFERROR((V11-K11)*IF(F11="Sell",-1,1)*R11*W11*IF(ISNUMBER(SEARCH("JPY",E11)),1000,IF(ISNUMBER(SEARCH("XAU",E11)),100,IF(OR(ISNUMBER(SEARCH("30",E11)),ISNUMBER(SEARCH("500",E11)),ISNUMBER(SEARCH("100",E11))),100,100000))),0)) | AA11: =IF(OR(Y11="",Z11=0),"",IFERROR((Y11-K11)*IF(F11="Sell",-1,1)*R11*Z11*IF(ISNUMBER(SEARCH("JPY",E11)),1000,IF(ISNUMBER(SEARCH("XAU",E11)),100,IF(OR(ISNUMBER(SEARCH("30",E11)),ISNUMBER(SEARCH("500",E11)),ISNUMBER(SEARCH("100",E11))),100,100000))),0)) | AC11: =IF(K11="","",1-IFERROR(T11,0)-IFERROR(W11,0)-IFERROR(Z11,0)) | AD11: =IF(AB11="","",IFERROR((IFERROR(S11*T11,0)+IFERROR(V11*W11,0)+IFERROR(Y11*Z11,0)+AB11*AC11)/(IFERROR(T11,0)+IFERROR(W11,0)+IFERROR(Z11,0)+AC11),AB11)) | AE11: =IF(AB11="","",IF(U11="",0,U11)+IF(X11="",0,X11)+IF(AA11="",0,AA11)+IFERROR((AB11-K11)*IF(F11="Sell",-1,1)*R11*AC11*IF(ISNUMBER(SEARCH("JPY",E11)),1000,IF(ISNUMBER(SEARCH("XAU",E11)),100,IF(OR(ISNUMBER(SEARCH("30",E11)),ISNUMBER(SEARCH("500",E11)),ISNUMBER(SEARCH("100",E11))),100,100000))),0)) | AF11: =IF(OR(K11="",M11="",L11=""),"",IFERROR(ABS(M11-K11)/ABS(K11-L11),0)) | AG11: =IF(OR(AE11="",AE11=0,Q11=0,Q11=""),"",IFERROR(AE11/Q11,0)) | AH11: =IF(AB11="","Open",IF(AG11="","Open",IF(AG11>0.1,"Win",IF(AG11<-0.1,"Loss","Breakeven")))) -> Open | AI11: =IF(OR(B11="",D11=""),"",D11-B11) | AJ11: =IF(AD11="","",IFERROR((AD11-K11)*IF(F11="Sell",-1,1)/IF(ISNUMBER(SEARCH("JPY",E11)),0.01,IF(ISNUMBER(SEARCH("XAU",E11)),0.01,IF(OR(ISNUMBER(SEARCH("30",E11)),ISNUMBER(SEARCH("500",E11)),ISNUMBER(SEARCH("100",E11))),1,0.0001))),0)) | AO11: =IF(AE11="","",IFERROR(IF(AO10="",SETTINGS!$B$6,AO10),SETTINGS!$B$6)+IF(AE11="",0,AE11))
A12: =IF(B12="","",ROW()-3) | P12: =IF(K12="","",IFERROR(ABS(K12-L12)/IF(ISNUMBER(SEARCH("JPY",E12)),0.01,IF(ISNUMBER(SEARCH("XAU",E12)),0.01,IF(OR(ISNUMBER(SEARCH("30",E12)),ISNUMBER(SEARCH("500",E12)),ISNUMBER(SEARCH("100",E12))),1,0.0001))),0)) | Q12: =IF(K12="","",SETTINGS!$B$6*O12) | R12: =IF(K12="","",IFERROR(Q12/(P12*IF(ISNUMBER(SEARCH("JPY",E12)),9.09,IF(ISNUMBER(SEARCH("XAU",E12)),1,IF(OR(ISNUMBER(SEARCH("30",E12)),ISNUMBER(SEARCH("500",E12)),ISNUMBER(SEARCH("100",E12))),1,10)))),0)) | U12: =IF(OR(S12="",T12=0),"",IFERROR((S12-K12)*IF(F12="Sell",-1,1)*R12*T12*IF(ISNUMBER(SEARCH("JPY",E12)),1000,IF(ISNUMBER(SEARCH("XAU",E12)),100,IF(OR(ISNUMBER(SEARCH("30",E12)),ISNUMBER(SEARCH("500",E12)),ISNUMBER(SEARCH("100",E12))),100,100000))),0)) | X12: =IF(OR(V12="",W12=0),"",IFERROR((V12-K12)*IF(F12="Sell",-1,1)*R12*W12*IF(ISNUMBER(SEARCH("JPY",E12)),1000,IF(ISNUMBER(SEARCH("XAU",E12)),100,IF(OR(ISNUMBER(SEARCH("30",E12)),ISNUMBER(SEARCH("500",E12)),ISNUMBER(SEARCH("100",E12))),100,100000))),0)) | AA12: =IF(OR(Y12="",Z12=0),"",IFERROR((Y12-K12)*IF(F12="Sell",-1,1)*R12*Z12*IF(ISNUMBER(SEARCH("JPY",E12)),1000,IF(ISNUMBER(SEARCH("XAU",E12)),100,IF(OR(ISNUMBER(SEARCH("30",E12)),ISNUMBER(SEARCH("500",E12)),ISNUMBER(SEARCH("100",E12))),100,100000))),0)) | AC12: =IF(K12="","",1-IFERROR(T12,0)-IFERROR(W12,0)-IFERROR(Z12,0)) | AD12: =IF(AB12="","",IFERROR((IFERROR(S12*T12,0)+IFERROR(V12*W12,0)+IFERROR(Y12*Z12,0)+AB12*AC12)/(IFERROR(T12,0)+IFERROR(W12,0)+IFERROR(Z12,0)+AC12),AB12)) | AE12: =IF(AB12="","",IF(U12="",0,U12)+IF(X12="",0,X12)+IF(AA12="",0,AA12)+IFERROR((AB12-K12)*IF(F12="Sell",-1,1)*R12*AC12*IF(ISNUMBER(SEARCH("JPY",E12)),1000,IF(ISNUMBER(SEARCH("XAU",E12)),100,IF(OR(ISNUMBER(SEARCH("30",E12)),ISNUMBER(SEARCH("500",E12)),ISNUMBER(SEARCH("100",E12))),100,100000))),0)) | AF12: =IF(OR(K12="",M12="",L12=""),"",IFERROR(ABS(M12-K12)/ABS(K12-L12),0)) | AG12: =IF(OR(AE12="",AE12=0,Q12=0,Q12=""),"",IFERROR(AE12/Q12,0)) | AH12: =IF(AB12="","Open",IF(AG12="","Open",IF(AG12>0.1,"Win",IF(AG12<-0.1,"Loss","Breakeven")))) -> Open | AI12: =IF(OR(B12="",D12=""),"",D12-B12) | AJ12: =IF(AD12="","",IFERROR((AD12-K12)*IF(F12="Sell",-1,1)/IF(ISNUMBER(SEARCH("JPY",E12)),0.01,IF(ISNUMBER(SEARCH("XAU",E12)),0.01,IF(OR(ISNUMBER(SEARCH("30",E12)),ISNUMBER(SEARCH("500",E12)),ISNUMBER(SEARCH("100",E12))),1,0.0001))),0)) | AO12: =IF(AE12="","",IFERROR(IF(AO11="",SETTINGS!$B$6,AO11),SETTINGS!$B$6)+IF(AE12="",0,AE12))
A13: =IF(B13="","",ROW()-3) | P13: =IF(K13="","",IFERROR(ABS(K13-L13)/IF(ISNUMBER(SEARCH("JPY",E13)),0.01,IF(ISNUMBER(SEARCH("XAU",E13)),0.01,IF(OR(ISNUMBER(SEARCH("30",E13)),ISNUMBER(SEARCH("500",E13)),ISNUMBER(SEARCH("100",E13))),1,0.0001))),0)) | Q13: =IF(K13="","",SETTINGS!$B$6*O13) | R13: =IF(K13="","",IFERROR(Q13/(P13*IF(ISNUMBER(SEARCH("JPY",E13)),9.09,IF(ISNUMBER(SEARCH("XAU",E13)),1,IF(OR(ISNUMBER(SEARCH("30",E13)),ISNUMBER(SEARCH("500",E13)),ISNUMBER(SEARCH("100",E13))),1,10)))),0)) | U13: =IF(OR(S13="",T13=0),"",IFERROR((S13-K13)*IF(F13="Sell",-1,1)*R13*T13*IF(ISNUMBER(SEARCH("JPY",E13)),1000,IF(ISNUMBER(SEARCH("XAU",E13)),100,IF(OR(ISNUMBER(SEARCH("30",E13)),ISNUMBER(SEARCH("500",E13)),ISNUMBER(SEARCH("100",E13))),100,100000))),0)) | X13: =IF(OR(V13="",W13=0),"",IFERROR((V13-K13)*IF(F13="Sell",-1,1)*R13*W13*IF(ISNUMBER(SEARCH("JPY",E13)),1000,IF(ISNUMBER(SEARCH("XAU",E13)),100,IF(OR(ISNUMBER(SEARCH("30",E13)),ISNUMBER(SEARCH("500",E13)),ISNUMBER(SEARCH("100",E13))),100,100000))),0)) | AA13: =IF(OR(Y13="",Z13=0),"",IFERROR((Y13-K13)*IF(F13="Sell",-1,1)*R13*Z13*IF(ISNUMBER(SEARCH("JPY",E13)),1000,IF(ISNUMBER(SEARCH("XAU",E13)),100,IF(OR(ISNUMBER(SEARCH("30",E13)),ISNUMBER(SEARCH("500",E13)),ISNUMBER(SEARCH("100",E13))),100,100000))),0)) | AC13: =IF(K13="","",1-IFERROR(T13,0)-IFERROR(W13,0)-IFERROR(Z13,0)) | AD13: =IF(AB13="","",IFERROR((IFERROR(S13*T13,0)+IFERROR(V13*W13,0)+IFERROR(Y13*Z13,0)+AB13*AC13)/(IFERROR(T13,0)+IFERROR(W13,0)+IFERROR(Z13,0)+AC13),AB13)) | AE13: =IF(AB13="","",IF(U13="",0,U13)+IF(X13="",0,X13)+IF(AA13="",0,AA13)+IFERROR((AB13-K13)*IF(F13="Sell",-1,1)*R13*AC13*IF(ISNUMBER(SEARCH("JPY",E13)),1000,IF(ISNUMBER(SEARCH("XAU",E13)),100,IF(OR(ISNUMBER(SEARCH("30",E13)),ISNUMBER(SEARCH("500",E13)),ISNUMBER(SEARCH("100",E13))),100,100000))),0)) | AF13: =IF(OR(K13="",M13="",L13=""),"",IFERROR(ABS(M13-K13)/ABS(K13-L13),0)) | AG13: =IF(OR(AE13="",AE13=0,Q13=0,Q13=""),"",IFERROR(AE13/Q13,0)) | AH13: =IF(AB13="","Open",IF(AG13="","Open",IF(AG13>0.1,"Win",IF(AG13<-0.1,"Loss","Breakeven")))) -> Open | AI13: =IF(OR(B13="",D13=""),"",D13-B13) | AJ13: =IF(AD13="","",IFERROR((AD13-K13)*IF(F13="Sell",-1,1)/IF(ISNUMBER(SEARCH("JPY",E13)),0.01,IF(ISNUMBER(SEARCH("XAU",E13)),0.01,IF(OR(ISNUMBER(SEARCH("30",E13)),ISNUMBER(SEARCH("500",E13)),ISNUMBER(SEARCH("100",E13))),1,0.0001))),0)) | AO13: =IF(AE13="","",IFERROR(IF(AO12="",SETTINGS!$B$6,AO12),SETTINGS!$B$6)+IF(AE13="",0,AE13))
A14: =IF(B14="","",ROW()-3) | P14: =IF(K14="","",IFERROR(ABS(K14-L14)/IF(ISNUMBER(SEARCH("JPY",E14)),0.01,IF(ISNUMBER(SEARCH("XAU",E14)),0.01,IF(OR(ISNUMBER(SEARCH("30",E14)),ISNUMBER(SEARCH("500",E14)),ISNUMBER(SEARCH("100",E14))),1,0.0001))),0)) | Q14: =IF(K14="","",SETTINGS!$B$6*O14) | R14: =IF(K14="","",IFERROR(Q14/(P14*IF(ISNUMBER(SEARCH("JPY",E14)),9.09,IF(ISNUMBER(SEARCH("XAU",E14)),1,IF(OR(ISNUMBER(SEARCH("30",E14)),ISNUMBER(SEARCH("500",E14)),ISNUMBER(SEARCH("100",E14))),1,10)))),0)) | U14: =IF(OR(S14="",T14=0),"",IFERROR((S14-K14)*IF(F14="Sell",-1,1)*R14*T14*IF(ISNUMBER(SEARCH("JPY",E14)),1000,IF(ISNUMBER(SEARCH("XAU",E14)),100,IF(OR(ISNUMBER(SEARCH("30",E14)),ISNUMBER(SEARCH("500",E14)),ISNUMBER(SEARCH("100",E14))),100,100000))),0)) | X14: =IF(OR(V14="",W14=0),"",IFERROR((V14-K14)*IF(F14="Sell",-1,1)*R14*W14*IF(ISNUMBER(SEARCH("JPY",E14)),1000,IF(ISNUMBER(SEARCH("XAU",E14)),100,IF(OR(ISNUMBER(SEARCH("30",E14)),ISNUMBER(SEARCH("500",E14)),ISNUMBER(SEARCH("100",E14))),100,100000))),0)) | AA14: =IF(OR(Y14="",Z14=0),"",IFERROR((Y14-K14)*IF(F14="Sell",-1,1)*R14*Z14*IF(ISNUMBER(SEARCH("JPY",E14)),1000,IF(ISNUMBER(SEARCH("XAU",E14)),100,IF(OR(ISNUMBER(SEARCH("30",E14)),ISNUMBER(SEARCH("500",E14)),ISNUMBER(SEARCH("100",E14))),100,100000))),0)) | AC14: =IF(K14="","",1-IFERROR(T14,0)-IFERROR(W14,0)-IFERROR(Z14,0)) | AD14: =IF(AB14="","",IFERROR((IFERROR(S14*T14,0)+IFERROR(V14*W14,0)+IFERROR(Y14*Z14,0)+AB14*AC14)/(IFERROR(T14,0)+IFERROR(W14,0)+IFERROR(Z14,0)+AC14),AB14)) | AE14: =IF(AB14="","",IF(U14="",0,U14)+IF(X14="",0,X14)+IF(AA14="",0,AA14)+IFERROR((AB14-K14)*IF(F14="Sell",-1,1)*R14*AC14*IF(ISNUMBER(SEARCH("JPY",E14)),1000,IF(ISNUMBER(SEARCH("XAU",E14)),100,IF(OR(ISNUMBER(SEARCH("30",E14)),ISNUMBER(SEARCH("500",E14)),ISNUMBER(SEARCH("100",E14))),100,100000))),0)) | AF14: =IF(OR(K14="",M14="",L14=""),"",IFERROR(ABS(M14-K14)/ABS(K14-L14),0)) | AG14: =IF(OR(AE14="",AE14=0,Q14=0,Q14=""),"",IFERROR(AE14/Q14,0)) | AH14: =IF(AB14="","Open",IF(AG14="","Open",IF(AG14>0.1,"Win",IF(AG14<-0.1,"Loss","Breakeven")))) -> Open | AI14: =IF(OR(B14="",D14=""),"",D14-B14) | AJ14: =IF(AD14="","",IFERROR((AD14-K14)*IF(F14="Sell",-1,1)/IF(ISNUMBER(SEARCH("JPY",E14)),0.01,IF(ISNUMBER(SEARCH("XAU",E14)),0.01,IF(OR(ISNUMBER(SEARCH("30",E14)),ISNUMBER(SEARCH("500",E14)),ISNUMBER(SEARCH("100",E14))),1,0.0001))),0)) | AO14: =IF(AE14="","",IFERROR(IF(AO13="",SETTINGS!$B$6,AO13),SETTINGS!$B$6)+IF(AE14="",0,AE14))
A15: =IF(B15="","",ROW()-3) | P15: =IF(K15="","",IFERROR(ABS(K15-L15)/IF(ISNUMBER(SEARCH("JPY",E15)),0.01,IF(ISNUMBER(SEARCH("XAU",E15)),0.01,IF(OR(ISNUMBER(SEARCH("30",E15)),ISNUMBER(SEARCH("500",E15)),ISNUMBER(SEARCH("100",E15))),1,0.0001))),0)) | Q15: =IF(K15="","",SETTINGS!$B$6*O15) | R15: =IF(K15="","",IFERROR(Q15/(P15*IF(ISNUMBER(SEARCH("JPY",E15)),9.09,IF(ISNUMBER(SEARCH("XAU",E15)),1,IF(OR(ISNUMBER(SEARCH("30",E15)),ISNUMBER(SEARCH("500",E15)),ISNUMBER(SEARCH("100",E15))),1,10)))),0)) | U15: =IF(OR(S15="",T15=0),"",IFERROR((S15-K15)*IF(F15="Sell",-1,1)*R15*T15*IF(ISNUMBER(SEARCH("JPY",E15)),1000,IF(ISNUMBER(SEARCH("XAU",E15)),100,IF(OR(ISNUMBER(SEARCH("30",E15)),ISNUMBER(SEARCH("500",E15)),ISNUMBER(SEARCH("100",E15))),100,100000))),0)) | X15: =IF(OR(V15="",W15=0),"",IFERROR((V15-K15)*IF(F15="Sell",-1,1)*R15*W15*IF(ISNUMBER(SEARCH("JPY",E15)),1000,IF(ISNUMBER(SEARCH("XAU",E15)),100,IF(OR(ISNUMBER(SEARCH("30",E15)),ISNUMBER(SEARCH("500",E15)),ISNUMBER(SEARCH("100",E15))),100,100000))),0)) | AA15: =IF(OR(Y15="",Z15=0),"",IFERROR((Y15-K15)*IF(F15="Sell",-1,1)*R15*Z15*IF(ISNUMBER(SEARCH("JPY",E15)),1000,IF(ISNUMBER(SEARCH("XAU",E15)),100,IF(OR(ISNUMBER(SEARCH("30",E15)),ISNUMBER(SEARCH("500",E15)),ISNUMBER(SEARCH("100",E15))),100,100000))),0)) | AC15: =IF(K15="","",1-IFERROR(T15,0)-IFERROR(W15,0)-IFERROR(Z15,0)) | AD15: =IF(AB15="","",IFERROR((IFERROR(S15*T15,0)+IFERROR(V15*W15,0)+IFERROR(Y15*Z15,0)+AB15*AC15)/(IFERROR(T15,0)+IFERROR(W15,0)+IFERROR(Z15,0)+AC15),AB15)) | AE15: =IF(AB15="","",IF(U15="",0,U15)+IF(X15="",0,X15)+IF(AA15="",0,AA15)+IFERROR((AB15-K15)*IF(F15="Sell",-1,1)*R15*AC15*IF(ISNUMBER(SEARCH("JPY",E15)),1000,IF(ISNUMBER(SEARCH("XAU",E15)),100,IF(OR(ISNUMBER(SEARCH("30",E15)),ISNUMBER(SEARCH("500",E15)),ISNUMBER(SEARCH("100",E15))),100,100000))),0)) | AF15: =IF(OR(K15="",M15="",L15=""),"",IFERROR(ABS(M15-K15)/ABS(K15-L15),0)) | AG15: =IF(OR(AE15="",AE15=0,Q15=0,Q15=""),"",IFERROR(AE15/Q15,0)) | AH15: =IF(AB15="","Open",IF(AG15="","Open",IF(AG15>0.1,"Win",IF(AG15<-0.1,"Loss","Breakeven")))) -> Open | AI15: =IF(OR(B15="",D15=""),"",D15-B15) | AJ15: =IF(AD15="","",IFERROR((AD15-K15)*IF(F15="Sell",-1,1)/IF(ISNUMBER(SEARCH("JPY",E15)),0.01,IF(ISNUMBER(SEARCH("XAU",E15)),0.01,IF(OR(ISNUMBER(SEARCH("30",E15)),ISNUMBER(SEARCH("500",E15)),ISNUMBER(SEARCH("100",E15))),1,0.0001))),0)) | AO15: =IF(AE15="","",IFERROR(IF(AO14="",SETTINGS!$B$6,AO14),SETTINGS!$B$6)+IF(AE15="",0,AE15))
A16: =IF(B16="","",ROW()-3) | P16: =IF(K16="","",IFERROR(ABS(K16-L16)/IF(ISNUMBER(SEARCH("JPY",E16)),0.01,IF(ISNUMBER(SEARCH("XAU",E16)),0.01,IF(OR(ISNUMBER(SEARCH("30",E16)),ISNUMBER(SEARCH("500",E16)),ISNUMBER(SEARCH("100",E16))),1,0.0001))),0)) | Q16: =IF(K16="","",SETTINGS!$B$6*O16) | R16: =IF(K16="","",IFERROR(Q16/(P16*IF(ISNUMBER(SEARCH("JPY",E16)),9.09,IF(ISNUMBER(SEARCH("XAU",E16)),1,IF(OR(ISNUMBER(SEARCH("30",E16)),ISNUMBER(SEARCH("500",E16)),ISNUMBER(SEARCH("100",E16))),1,10)))),0)) | U16: =IF(OR(S16="",T16=0),"",IFERROR((S16-K16)*IF(F16="Sell",-1,1)*R16*T16*IF(ISNUMBER(SEARCH("JPY",E16)),1000,IF(ISNUMBER(SEARCH("XAU",E16)),100,IF(OR(ISNUMBER(SEARCH("30",E16)),ISNUMBER(SEARCH("500",E16)),ISNUMBER(SEARCH("100",E16))),100,100000))),0)) | X16: =IF(OR(V16="",W16=0),"",IFERROR((V16-K16)*IF(F16="Sell",-1,1)*R16*W16*IF(ISNUMBER(SEARCH("JPY",E16)),1000,IF(ISNUMBER(SEARCH("XAU",E16)),100,IF(OR(ISNUMBER(SEARCH("30",E16)),ISNUMBER(SEARCH("500",E16)),ISNUMBER(SEARCH("100",E16))),100,100000))),0)) | AA16: =IF(OR(Y16="",Z16=0),"",IFERROR((Y16-K16)*IF(F16="Sell",-1,1)*R16*Z16*IF(ISNUMBER(SEARCH("JPY",E16)),1000,IF(ISNUMBER(SEARCH("XAU",E16)),100,IF(OR(ISNUMBER(SEARCH("30",E16)),ISNUMBER(SEARCH("500",E16)),ISNUMBER(SEARCH("100",E16))),100,100000))),0)) | AC16: =IF(K16="","",1-IFERROR(T16,0)-IFERROR(W16,0)-IFERROR(Z16,0)) | AD16: =IF(AB16="","",IFERROR((IFERROR(S16*T16,0)+IFERROR(V16*W16,0)+IFERROR(Y16*Z16,0)+AB16*AC16)/(IFERROR(T16,0)+IFERROR(W16,0)+IFERROR(Z16,0)+AC16),AB16)) | AE16: =IF(AB16="","",IF(U16="",0,U16)+IF(X16="",0,X16)+IF(AA16="",0,AA16)+IFERROR((AB16-K16)*IF(F16="Sell",-1,1)*R16*AC16*IF(ISNUMBER(SEARCH("JPY",E16)),1000,IF(ISNUMBER(SEARCH("XAU",E16)),100,IF(OR(ISNUMBER(SEARCH("30",E16)),ISNUMBER(SEARCH("500",E16)),ISNUMBER(SEARCH("100",E16))),100,100000))),0)) | AF16: =IF(OR(K16="",M16="",L16=""),"",IFERROR(ABS(M16-K16)/ABS(K16-L16),0)) | AG16: =IF(OR(AE16="",AE16=0,Q16=0,Q16=""),"",IFERROR(AE16/Q16,0)) | AH16: =IF(AB16="","Open",IF(AG16="","Open",IF(AG16>0.1,"Win",IF(AG16<-0.1,"Loss","Breakeven")))) -> Open | AI16: =IF(OR(B16="",D16=""),"",D16-B16) | AJ16: =IF(AD16="","",IFERROR((AD16-K16)*IF(F16="Sell",-1,1)/IF(ISNUMBER(SEARCH("JPY",E16)),0.01,IF(ISNUMBER(SEARCH("XAU",E16)),0.01,IF(OR(ISNUMBER(SEARCH("30",E16)),ISNUMBER(SEARCH("500",E16)),ISNUMBER(SEARCH("100",E16))),1,0.0001))),0)) | AO16: =IF(AE16="","",IFERROR(IF(AO15="",SETTINGS!$B$6,AO15),SETTINGS!$B$6)+IF(AE16="",0,AE16))
A17: =IF(B17="","",ROW()-3) | P17: =IF(K17="","",IFERROR(ABS(K17-L17)/IF(ISNUMBER(SEARCH("JPY",E17)),0.01,IF(ISNUMBER(SEARCH("XAU",E17)),0.01,IF(OR(ISNUMBER(SEARCH("30",E17)),ISNUMBER(SEARCH("500",E17)),ISNUMBER(SEARCH("100",E17))),1,0.0001))),0)) | Q17: =IF(K17="","",SETTINGS!$B$6*O17) | R17: =IF(K17="","",IFERROR(Q17/(P17*IF(ISNUMBER(SEARCH("JPY",E17)),9.09,IF(ISNUMBER(SEARCH("XAU",E17)),1,IF(OR(ISNUMBER(SEARCH("30",E17)),ISNUMBER(SEARCH("500",E17)),ISNUMBER(SEARCH("100",E17))),1,10)))),0)) | U17: =IF(OR(S17="",T17=0),"",IFERROR((S17-K17)*IF(F17="Sell",-1,1)*R17*T17*IF(ISNUMBER(SEARCH("JPY",E17)),1000,IF(ISNUMBER(SEARCH("XAU",E17)),100,IF(OR(ISNUMBER(SEARCH("30",E17)),ISNUMBER(SEARCH("500",E17)),ISNUMBER(SEARCH("100",E17))),100,100000))),0)) | X17: =IF(OR(V17="",W17=0),"",IFERROR((V17-K17)*IF(F17="Sell",-1,1)*R17*W17*IF(ISNUMBER(SEARCH("JPY",E17)),1000,IF(ISNUMBER(SEARCH("XAU",E17)),100,IF(OR(ISNUMBER(SEARCH("30",E17)),ISNUMBER(SEARCH("500",E17)),ISNUMBER(SEARCH("100",E17))),100,100000))),0)) | AA17: =IF(OR(Y17="",Z17=0),"",IFERROR((Y17-K17)*IF(F17="Sell",-1,1)*R17*Z17*IF(ISNUMBER(SEARCH("JPY",E17)),1000,IF(ISNUMBER(SEARCH("XAU",E17)),100,IF(OR(ISNUMBER(SEARCH("30",E17)),ISNUMBER(SEARCH("500",E17)),ISNUMBER(SEARCH("100",E17))),100,100000))),0)) | AC17: =IF(K17="","",1-IFERROR(T17,0)-IFERROR(W17,0)-IFERROR(Z17,0)) | AD17: =IF(AB17="","",IFERROR((IFERROR(S17*T17,0)+IFERROR(V17*W17,0)+IFERROR(Y17*Z17,0)+AB17*AC17)/(IFERROR(T17,0)+IFERROR(W17,0)+IFERROR(Z17,0)+AC17),AB17)) | AE17: =IF(AB17="","",IF(U17="",0,U17)+IF(X17="",0,X17)+IF(AA17="",0,AA17)+IFERROR((AB17-K17)*IF(F17="Sell",-1,1)*R17*AC17*IF(ISNUMBER(SEARCH("JPY",E17)),1000,IF(ISNUMBER(SEARCH("XAU",E17)),100,IF(OR(ISNUMBER(SEARCH("30",E17)),ISNUMBER(SEARCH("500",E17)),ISNUMBER(SEARCH("100",E17))),100,100000))),0)) | AF17: =IF(OR(K17="",M17="",L17=""),"",IFERROR(ABS(M17-K17)/ABS(K17-L17),0)) | AG17: =IF(OR(AE17="",AE17=0,Q17=0,Q17=""),"",IFERROR(AE17/Q17,0)) | AH17: =IF(AB17="","Open",IF(AG17="","Open",IF(AG17>0.1,"Win",IF(AG17<-0.1,"Loss","Breakeven")))) -> Open | AI17: =IF(OR(B17="",D17=""),"",D17-B17) | AJ17: =IF(AD17="","",IFERROR((AD17-K17)*IF(F17="Sell",-1,1)/IF(ISNUMBER(SEARCH("JPY",E17)),0.01,IF(ISNUMBER(SEARCH("XAU",E17)),0.01,IF(OR(ISNUMBER(SEARCH("30",E17)),ISNUMBER(SEARCH("500",E17)),ISNUMBER(SEARCH("100",E17))),1,0.0001))),0)) | AO17: =IF(AE17="","",IFERROR(IF(AO16="",SETTINGS!$B$6,AO16),SETTINGS!$B$6)+IF(AE17="",0,AE17))
A18: =IF(B18="","",ROW()-3) | P18: =IF(K18="","",IFERROR(ABS(K18-L18)/IF(ISNUMBER(SEARCH("JPY",E18)),0.01,IF(ISNUMBER(SEARCH("XAU",E18)),0.01,IF(OR(ISNUMBER(SEARCH("30",E18)),ISNUMBER(SEARCH("500",E18)),ISNUMBER(SEARCH("100",E18))),1,0.0001))),0)) | Q18: =IF(K18="","",SETTINGS!$B$6*O18) | R18: =IF(K18="","",IFERROR(Q18/(P18*IF(ISNUMBER(SEARCH("JPY",E18)),9.09,IF(ISNUMBER(SEARCH("XAU",E18)),1,IF(OR(ISNUMBER(SEARCH("30",E18)),ISNUMBER(SEARCH("500",E18)),ISNUMBER(SEARCH("100",E18))),1,10)))),0)) | U18: =IF(OR(S18="",T18=0),"",IFERROR((S18-K18)*IF(F18="Sell",-1,1)*R18*T18*IF(ISNUMBER(SEARCH("JPY",E18)),1000,IF(ISNUMBER(SEARCH("XAU",E18)),100,IF(OR(ISNUMBER(SEARCH("30",E18)),ISNUMBER(SEARCH("500",E18)),ISNUMBER(SEARCH("100",E18))),100,100000))),0)) | X18: =IF(OR(V18="",W18=0),"",IFERROR((V18-K18)*IF(F18="Sell",-1,1)*R18*W18*IF(ISNUMBER(SEARCH("JPY",E18)),1000,IF(ISNUMBER(SEARCH("XAU",E18)),100,IF(OR(ISNUMBER(SEARCH("30",E18)),ISNUMBER(SEARCH("500",E18)),ISNUMBER(SEARCH("100",E18))),100,100000))),0)) | AA18: =IF(OR(Y18="",Z18=0),"",IFERROR((Y18-K18)*IF(F18="Sell",-1,1)*R18*Z18*IF(ISNUMBER(SEARCH("JPY",E18)),1000,IF(ISNUMBER(SEARCH("XAU",E18)),100,IF(OR(ISNUMBER(SEARCH("30",E18)),ISNUMBER(SEARCH("500",E18)),ISNUMBER(SEARCH("100",E18))),100,100000))),0)) | AC18: =IF(K18="","",1-IFERROR(T18,0)-IFERROR(W18,0)-IFERROR(Z18,0)) | AD18: =IF(AB18="","",IFERROR((IFERROR(S18*T18,0)+IFERROR(V18*W18,0)+IFERROR(Y18*Z18,0)+AB18*AC18)/(IFERROR(T18,0)+IFERROR(W18,0)+IFERROR(Z18,0)+AC18),AB18)) | AE18: =IF(AB18="","",IF(U18="",0,U18)+IF(X18="",0,X18)+IF(AA18="",0,AA18)+IFERROR((AB18-K18)*IF(F18="Sell",-1,1)*R18*AC18*IF(ISNUMBER(SEARCH("JPY",E18)),1000,IF(ISNUMBER(SEARCH("XAU",E18)),100,IF(OR(ISNUMBER(SEARCH("30",E18)),ISNUMBER(SEARCH("500",E18)),ISNUMBER(SEARCH("100",E18))),100,100000))),0)) | AF18: =IF(OR(K18="",M18="",L18=""),"",IFERROR(ABS(M18-K18)/ABS(K18-L18),0)) | AG18: =IF(OR(AE18="",AE18=0,Q18=0,Q18=""),"",IFERROR(AE18/Q18,0)) | AH18: =IF(AB18="","Open",IF(AG18="","Open",IF(AG18>0.1,"Win",IF(AG18<-0.1,"Loss","Breakeven")))) -> Open | AI18: =IF(OR(B18="",D18=""),"",D18-B18) | AJ18: =IF(AD18="","",IFERROR((AD18-K18)*IF(F18="Sell",-1,1)/IF(ISNUMBER(SEARCH("JPY",E18)),0.01,IF(ISNUMBER(SEARCH("XAU",E18)),0.01,IF(OR(ISNUMBER(SEARCH("30",E18)),ISNUMBER(SEARCH("500",E18)),ISNUMBER(SEARCH("100",E18))),1,0.0001))),0)) | AO18: =IF(AE18="","",IFERROR(IF(AO17="",SETTINGS!$B$6,AO17),SETTINGS!$B$6)+IF(AE18="",0,AE18))
A19: =IF(B19="","",ROW()-3) | P19: =IF(K19="","",IFERROR(ABS(K19-L19)/IF(ISNUMBER(SEARCH("JPY",E19)),0.01,IF(ISNUMBER(SEARCH("XAU",E19)),0.01,IF(OR(ISNUMBER(SEARCH("30",E19)),ISNUMBER(SEARCH("500",E19)),ISNUMBER(SEARCH("100",E19))),1,0.0001))),0)) | Q19: =IF(K19="","",SETTINGS!$B$6*O19) | R19: =IF(K19="","",IFERROR(Q19/(P19*IF(ISNUMBER(SEARCH("JPY",E19)),9.09,IF(ISNUMBER(SEARCH("XAU",E19)),1,IF(OR(ISNUMBER(SEARCH("30",E19)),ISNUMBER(SEARCH("500",E19)),ISNUMBER(SEARCH("100",E19))),1,10)))),0)) | U19: =IF(OR(S19="",T19=0),"",IFERROR((S19-K19)*IF(F19="Sell",-1,1)*R19*T19*IF(ISNUMBER(SEARCH("JPY",E19)),1000,IF(ISNUMBER(SEARCH("XAU",E19)),100,IF(OR(ISNUMBER(SEARCH("30",E19)),ISNUMBER(SEARCH("500",E19)),ISNUMBER(SEARCH("100",E19))),100,100000))),0)) | X19: =IF(OR(V19="",W19=0),"",IFERROR((V19-K19)*IF(F19="Sell",-1,1)*R19*W19*IF(ISNUMBER(SEARCH("JPY",E19)),1000,IF(ISNUMBER(SEARCH("XAU",E19)),100,IF(OR(ISNUMBER(SEARCH("30",E19)),ISNUMBER(SEARCH("500",E19)),ISNUMBER(SEARCH("100",E19))),100,100000))),0)) | AA19: =IF(OR(Y19="",Z19=0),"",IFERROR((Y19-K19)*IF(F19="Sell",-1,1)*R19*Z19*IF(ISNUMBER(SEARCH("JPY",E19)),1000,IF(ISNUMBER(SEARCH("XAU",E19)),100,IF(OR(ISNUMBER(SEARCH("30",E19)),ISNUMBER(SEARCH("500",E19)),ISNUMBER(SEARCH("100",E19))),100,100000))),0)) | AC19: =IF(K19="","",1-IFERROR(T19,0)-IFERROR(W19,0)-IFERROR(Z19,0)) | AD19: =IF(AB19="","",IFERROR((IFERROR(S19*T19,0)+IFERROR(V19*W19,0)+IFERROR(Y19*Z19,0)+AB19*AC19)/(IFERROR(T19,0)+IFERROR(W19,0)+IFERROR(Z19,0)+AC19),AB19)) | AE19: =IF(AB19="","",IF(U19="",0,U19)+IF(X19="",0,X19)+IF(AA19="",0,AA19)+IFERROR((AB19-K19)*IF(F19="Sell",-1,1)*R19*AC19*IF(ISNUMBER(SEARCH("JPY",E19)),1000,IF(ISNUMBER(SEARCH("XAU",E19)),100,IF(OR(ISNUMBER(SEARCH("30",E19)),ISNUMBER(SEARCH("500",E19)),ISNUMBER(SEARCH("100",E19))),100,100000))),0)) | AF19: =IF(OR(K19="",M19="",L19=""),"",IFERROR(ABS(M19-K19)/ABS(K19-L19),0)) | AG19: =IF(OR(AE19="",AE19=0,Q19=0,Q19=""),"",IFERROR(AE19/Q19,0)) | AH19: =IF(AB19="","Open",IF(AG19="","Open",IF(AG19>0.1,"Win",IF(AG19<-0.1,"Loss","Breakeven")))) -> Open | AI19: =IF(OR(B19="",D19=""),"",D19-B19) | AJ19: =IF(AD19="","",IFERROR((AD19-K19)*IF(F19="Sell",-1,1)/IF(ISNUMBER(SEARCH("JPY",E19)),0.01,IF(ISNUMBER(SEARCH("XAU",E19)),0.01,IF(OR(ISNUMBER(SEARCH("30",E19)),ISNUMBER(SEARCH("500",E19)),ISNUMBER(SEARCH("100",E19))),1,0.0001))),0)) | AO19: =IF(AE19="","",IFERROR(IF(AO18="",SETTINGS!$B$6,AO18),SETTINGS!$B$6)+IF(AE19="",0,AE19))
A20: =IF(B20="","",ROW()-3) | P20: =IF(K20="","",IFERROR(ABS(K20-L20)/IF(ISNUMBER(SEARCH("JPY",E20)),0.01,IF(ISNUMBER(SEARCH("XAU",E20)),0.01,IF(OR(ISNUMBER(SEARCH("30",E20)),ISNUMBER(SEARCH("500",E20)),ISNUMBER(SEARCH("100",E20))),1,0.0001))),0)) | Q20: =IF(K20="","",SETTINGS!$B$6*O20) | R20: =IF(K20="","",IFERROR(Q20/(P20*IF(ISNUMBER(SEARCH("JPY",E20)),9.09,IF(ISNUMBER(SEARCH("XAU",E20)),1,IF(OR(ISNUMBER(SEARCH("30",E20)),ISNUMBER(SEARCH("500",E20)),ISNUMBER(SEARCH("100",E20))),1,10)))),0)) | U20: =IF(OR(S20="",T20=0),"",IFERROR((S20-K20)*IF(F20="Sell",-1,1)*R20*T20*IF(ISNUMBER(SEARCH("JPY",E20)),1000,IF(ISNUMBER(SEARCH("XAU",E20)),100,IF(OR(ISNUMBER(SEARCH("30",E20)),ISNUMBER(SEARCH("500",E20)),ISNUMBER(SEARCH("100",E20))),100,100000))),0)) | X20: =IF(OR(V20="",W20=0),"",IFERROR((V20-K20)*IF(F20="Sell",-1,1)*R20*W20*IF(ISNUMBER(SEARCH("JPY",E20)),1000,IF(ISNUMBER(SEARCH("XAU",E20)),100,IF(OR(ISNUMBER(SEARCH("30",E20)),ISNUMBER(SEARCH("500",E20)),ISNUMBER(SEARCH("100",E20))),100,100000))),0)) | AA20: =IF(OR(Y20="",Z20=0),"",IFERROR((Y20-K20)*IF(F20="Sell",-1,1)*R20*Z20*IF(ISNUMBER(SEARCH("JPY",E20)),1000,IF(ISNUMBER(SEARCH("XAU",E20)),100,IF(OR(ISNUMBER(SEARCH("30",E20)),ISNUMBER(SEARCH("500",E20)),ISNUMBER(SEARCH("100",E20))),100,100000))),0)) | AC20: =IF(K20="","",1-IFERROR(T20,0)-IFERROR(W20,0)-IFERROR(Z20,0)) | AD20: =IF(AB20="","",IFERROR((IFERROR(S20*T20,0)+IFERROR(V20*W20,0)+IFERROR(Y20*Z20,0)+AB20*AC20)/(IFERROR(T20,0)+IFERROR(W20,0)+IFERROR(Z20,0)+AC20),AB20)) | AE20: =IF(AB20="","",IF(U20="",0,U20)+IF(X20="",0,X20)+IF(AA20="",0,AA20)+IFERROR((AB20-K20)*IF(F20="Sell",-1,1)*R20*AC20*IF(ISNUMBER(SEARCH("JPY",E20)),1000,IF(ISNUMBER(SEARCH("XAU",E20)),100,IF(OR(ISNUMBER(SEARCH("30",E20)),ISNUMBER(SEARCH("500",E20)),ISNUMBER(SEARCH("100",E20))),100,100000))),0)) | AF20: =IF(OR(K20="",M20="",L20=""),"",IFERROR(ABS(M20-K20)/ABS(K20-L20),0)) | AG20: =IF(OR(AE20="",AE20=0,Q20=0,Q20=""),"",IFERROR(AE20/Q20,0)) | AH20: =IF(AB20="","Open",IF(AG20="","Open",IF(AG20>0.1,"Win",IF(AG20<-0.1,"Loss","Breakeven")))) -> Open | AI20: =IF(OR(B20="",D20=""),"",D20-B20) | AJ20: =IF(AD20="","",IFERROR((AD20-K20)*IF(F20="Sell",-1,1)/IF(ISNUMBER(SEARCH("JPY",E20)),0.01,IF(ISNUMBER(SEARCH("XAU",E20)),0.01,IF(OR(ISNUMBER(SEARCH("30",E20)),ISNUMBER(SEARCH("500",E20)),ISNUMBER(SEARCH("100",E20))),1,0.0001))),0)) | AO20: =IF(AE20="","",IFERROR(IF(AO19="",SETTINGS!$B$6,AO19),SETTINGS!$B$6)+IF(AE20="",0,AE20))
... A503: =IF(B503="","",ROW()-3) | P503: =IF(K503="","",IFERROR(ABS(K503-L503)/IF(ISNUMBER(SEARCH("JPY",E503)),0.01,IF(ISNUMBER(SEARCH("XAU",E503)),0.01,IF(OR(ISNUMBER(SEARCH("30",E503)),ISNUMBER(SEARCH("500",E503)),ISNUMBER(SEARCH("100",E503))),1,0.0001))),0)) | Q503: =IF(K503="","",SETTINGS!$B$6*O503) | R503: =IF(K503="","",IFERROR(Q503/(P503*IF(ISNUMBER(SEARCH("JPY",E503)),9.09,IF(ISNUMBER(SEARCH("XAU",E503)),1,IF(OR(ISNUMBER(SEARCH("30",E503)),ISNUMBER(SEARCH("500",E503)),ISNUMBER(SEARCH("100",E503))),1,10)))),0)) | U503: =IF(OR(S503="",T503=0),"",IFERROR((S503-K503)*IF(F503="Sell",-1,1)*R503*T503*IF(ISNUMBER(SEARCH("JPY",E503)),1000,IF(ISNUMBER(SEARCH("XAU",E503)),100,IF(OR(ISNUMBER(SEARCH("30",E503)),ISNUMBER(SEARCH("500",E503)),ISNUMBER(SEARCH("100",E503))),100,100000))),0)) | X503: =IF(OR(V503="",W503=0),"",IFERROR((V503-K503)*IF(F503="Sell",-1,1)*R503*W503*IF(ISNUMBER(SEARCH("JPY",E503)),1000,IF(ISNUMBER(SEARCH("XAU",E503)),100,IF(OR(ISNUMBER(SEARCH("30",E503)),ISNUMBER(SEARCH("500",E503)),ISNUMBER(SEARCH("100",E503))),100,100000))),0)) | AA503: =IF(OR(Y503="",Z503=0),"",IFERROR((Y503-K503)*IF(F503="Sell",-1,1)*R503*Z503*IF(ISNUMBER(SEARCH("JPY",E503)),1000,IF(ISNUMBER(SEARCH("XAU",E503)),100,IF(OR(ISNUMBER(SEARCH("30",E503)),ISNUMBER(SEARCH("500",E503)),ISNUMBER(SEARCH("100",E503))),100,100000))),0)) | AC503: =IF(K503="","",1-IFERROR(T503,0)-IFERROR(W503,0)-IFERROR(Z503,0)) | AD503: =IF(AB503="","",IFERROR((IFERROR(S503*T503,0)+IFERROR(V503*W503,0)+IFERROR(Y503*Z503,0)+AB503*AC503)/(IFERROR(T503,0)+IFERROR(W503,0)+IFERROR(Z503,0)+AC503),AB503)) | AE503: =IF(AB503="","",IF(U503="",0,U503)+IF(X503="",0,X503)+IF(AA503="",0,AA503)+IFERROR((AB503-K503)*IF(F503="Sell",-1,1)*R503*AC503*IF(ISNUMBER(SEARCH("JPY",E503)),1000,IF(ISNUMBER(SEARCH("XAU",E503)),100,IF(OR(ISNUMBER(SEARCH("30",E503)),ISNUMBER(SEARCH("500",E503)),ISNUMBER(SEARCH("100",E503))),100,100000))),0)) | AF503: =IF(OR(K503="",M503="",L503=""),"",IFERROR(ABS(M503-K503)/ABS(K503-L503),0)) | AG503: =IF(OR(AE503="",AE503=0,Q503=0,Q503=""),"",IFERROR(AE503/Q503,0)) | AH503: =IF(AB503="","Open",IF(AG503="","Open",IF(AG503>0.1,"Win",IF(AG503<-0.1,"Loss","Breakeven")))) -> Open | AI503: =IF(OR(B503="",D503=""),"",D503-B503) | AJ503: =IF(AD503="","",IFERROR((AD503-K503)*IF(F503="Sell",-1,1)/IF(ISNUMBER(SEARCH("JPY",E503)),0.01,IF(ISNUMBER(SEARCH("XAU",E503)),0.01,IF(OR(ISNUMBER(SEARCH("30",E503)),ISNUMBER(SEARCH("500",E503)),ISNUMBER(SEARCH("100",E503))),1,0.0001))),0)) | AO503: =IF(AE503="","",IFERROR(IF(AO502="",SETTINGS!$B$6,AO502),SETTINGS!$B$6)+IF(AE503="",0,AE503))

Sheet POSITION_CALC
A1: 🔢 POSITION SIZE CALCULATOR — Forex, Gold & Indices
A2: BLUE cells = user input. Results update automatically. Account balance pulled from SETTINGS.
A4: INPUTS
A5: Account Balance ($) | C5: =SETTINGS!B6 -> 50000
A6: Risk per Trade (%) | C6: =SETTINGS!B8 -> 0.01
A7: Risk Amount ($) | C7: =C5*C6 -> 500
A8: Instrument Type | C8: Forex Non-JPY
A9: Instrument | C9: EUR/USD
A10: Entry Price | C10: 1.085
A11: Stop Loss Price | C11: 1.083
A12: Stop Distance (pips/pts) | C12: =IFERROR(ABS(C10-C11)/IF(C8="Forex JPY",0.01,IF(C8="Gold XAUUSD",0.01,IF(C8="Indices",1,0.0001))),0) -> 20
A13: Account Currency | C13: =SETTINGS!B5 -> USD
A16: CALCULATED POSITION SIZES
A17: Market Type | B17: Pip/Pt Value (std lot) | C17: Lot Size | D17: Mini Lots | E17: Units | F17: Risk Validation
A18: Forex Non-JPY | B18: =10 -> 10 | C18: =IFERROR(C7/(ABS(C10-C11)/0.0001*10),0) -> 2.5 | D18: =G18*10 -> 0 | E18: =G18*100000 -> 0 | F18: =IF(ABS(G18*ABS(C10-C11)/0.0001*10-C7)<0.01,"✓ OK","⚠ Check") -> ⚠ Check
A19: Forex JPY | B19: =9.09 -> 9.09 | C19: =IFERROR(C7/(ABS(C10-C11)/0.01*9.09),0) -> 275.0275 | D19: =G19*10 -> 0 | E19: =G19*100000 -> 0 | F19: =IF(ABS(G19*ABS(C10-C11)/0.01*9.09-C7)<0.01,"✓ OK","⚠ Check") -> ⚠ Check
A20: Gold XAUUSD | B20: =1 -> 1 | C20: =IFERROR(C7/(ABS(C10-C11)/0.01*1),0) -> 2500 | D20: =G20*10 -> 0 | E20: =G20*100 -> 0 | F20: =IF(ABS(G20*ABS(C10-C11)/0.01*1-C7)<0.01,"✓ OK","⚠ Check") -> ⚠ Check
A21: Indices | B21: =1 -> 1 | C21: =IFERROR(C7/(ABS(C10-C11)/1*1),0) -> 250000 | D21: =G21*10 -> 0 | E21: =G21*100 -> 0 | F21: =IF(ABS(G21*ABS(C10-C11)/1*1-C7)<0.01,"✓ OK","⚠ Check") -> ⚠ Check
A24: ► RECOMMENDED LOT SIZE (for selected instrument type above)
A25: Selected Lot Size: | C25: =IFERROR(IF(C8="Forex Non-JPY",G18,IF(C8="Forex JPY",G19,IF(C8="Gold XAUUSD",G20,IF(C8="Indices",G21,0)))),0) -> 0 | D25: Dollar Risk: | F25: =C7 -> 500
A28: 📐 POSITION SIZING LOGIC: Forex Non-JPY: Lots = Risk$ ÷ (SL_pips × $10) | Forex JPY: Lots = Risk$ ÷ (SL_pips × $9.09) | Gold: Lots = Risk$ ÷ (SL_pts × $1 × 100oz) | Indices: Lots = Risk$ ÷ (SL_pts × $1) NOTE: JPY pip value = 1000÷USD/JPY_rate — approximated at $9.09. Adjust the pip value reference in SETTINGS for precision.

Sheet STRATEGY_PERF
A1: 📈 STRATEGY PERFORMANCE ANALYTICS
A2: Auto-updates from TRADE_LOG. No manual input required. Formulas reference column H (Strategy) and AG (R-Multiple).
A4: Strategy | B4: Total Trades | C4: Wins | D4: Losses | E4: Breakeven | F4: Win Rate | G4: Avg R-Multiple | H4: Avg Win R | I4: Avg Loss R | J4: Best Trade R | K4: Worst Trade R | L4: Total P/L $ | M4: Avg P/L $ | N4: Expectancy | O4: Profit Factor | P4: Notes
A5: Breakout | B5: =COUNTIF(TRADE_LOG!$H$4:$H$5003,A5) -> 1 | C5: =COUNTIFS(TRADE_LOG!$H$4:$H$5003,A5,TRADE_LOG!$AH$4:$AH$5003,"Win") -> 1 | D5: =COUNTIFS(TRADE_LOG!$H$4:$H$5003,A5,TRADE_LOG!$AH$4:$AH$5003,"Loss") -> 0 | E5: =COUNTIFS(TRADE_LOG!$H$4:$H$5003,A5,TRADE_LOG!$AH$4:$AH$5003,"Breakeven") -> 0 | F5: =IFERROR(C5/B5,0) -> 1 | G5: =IFERROR(AVERAGEIF(TRADE_LOG!$H$4:$H$5003,A5,TRADE_LOG!$AG$4:$AG$5003),0) -> 2.3933333 | H5: =IFERROR(AVERAGEIFS(TRADE_LOG!$AG$4:$AG$5003,TRADE_LOG!$H$4:$H$5003,A5,TRADE_LOG!$AH$4:$AH$5003,"Win"),0) -> 2.3933333 | I5: =IFERROR(AVERAGEIFS(TRADE_LOG!$AG$4:$AG$5003,TRADE_LOG!$H$4:$H$5003,A5,TRADE_LOG!$AH$4:$AH$5003,"Loss"),0) -> 0 | J5: =IFERROR(maxifs(TRADE_LOG!$AG$4:$AG$5003,TRADE_LOG!$H$4:$H$5003,A5),0) -> 0 | K5: =IFERROR(minifs(TRADE_LOG!$AG$4:$AG$5003,TRADE_LOG!$H$4:$H$5003,A5),0) -> 0 | L5: =IFERROR(SUMIF(TRADE_LOG!$H$4:$H$5003,A5,TRADE_LOG!$AE$4:$AE$5003),0) -> 1795 | M5: =IFERROR(L5/B5,0) -> 1795 | N5: =IFERROR(F5*H5+(1-F5)*I5,0) -> 2.3933333 | O5: =IFERROR((C5*H5)/(D5*ABS(I5)),0) -> 0
A6: Trend Follow | B6: =COUNTIF(TRADE_LOG!$H$4:$H$5003,A6) -> 1 | C6: =COUNTIFS(TRADE_LOG!$H$4:$H$5003,A6,TRADE_LOG!$AH$4:$AH$5003,"Win") -> 1 | D6: =COUNTIFS(TRADE_LOG!$H$4:$H$5003,A6,TRADE_LOG!$AH$4:$AH$5003,"Loss") -> 0 | E6: =COUNTIFS(TRADE_LOG!$H$4:$H$5003,A6,TRADE_LOG!$AH$4:$AH$5003,"Breakeven") -> 0 | F6: =IFERROR(C6/B6,0) -> 1 | G6: =IFERROR(AVERAGEIF(TRADE_LOG!$H$4:$H$5003,A6,TRADE_LOG!$AG$4:$AG$5003),0) -> 2.275 | H6: =IFERROR(AVERAGEIFS(TRADE_LOG!$AG$4:$AG$5003,TRADE_LOG!$H$4:$H$5003,A6,TRADE_LOG!$AH$4:$AH$5003,"Win"),0) -> 2.275 | I6: =IFERROR(AVERAGEIFS(TRADE_LOG!$AG$4:$AG$5003,TRADE_LOG!$H$4:$H$5003,A6,TRADE_LOG!$AH$4:$AH$5003,"Loss"),0) -> 0 | J6: =IFERROR(maxifs(TRADE_LOG!$AG$4:$AG$5003,TRADE_LOG!$H$4:$H$5003,A6),0) -> 0 | K6: =IFERROR(minifs(TRADE_LOG!$AG$4:$AG$5003,TRADE_LOG!$H$4:$H$5003,A6),0) -> 0 | L6: =IFERROR(SUMIF(TRADE_LOG!$H$4:$H$5003,A6,TRADE_LOG!$AE$4:$AE$5003),0) -> 1137.5 | M6: =IFERROR(L6/B6,0) -> 1137.5 | N6: =IFERROR(F6*H6+(1-F6)*I6,0) -> 2.275 | O6: =IFERROR((C6*H6)/(D6*ABS(I6)),0) -> 0
A7: Mean Reversion | B7: =COUNTIF(TRADE_LOG!$H$4:$H$5003,A7) -> 1 | C7: =COUNTIFS(TRADE_LOG!$H$4:$H$5003,A7,TRADE_LOG!$AH$4:$AH$5003,"Win") -> 1 | D7: =COUNTIFS(TRADE_LOG!$H$4:$H$5003,A7,TRADE_LOG!$AH$4:$AH$5003,"Loss") -> 0 | E7: =COUNTIFS(TRADE_LOG!$H$4:$H$5003,A7,TRADE_LOG!$AH$4:$AH$5003,"Breakeven") -> 0 | F7: =IFERROR(C7/B7,0) -> 1 | G7: =IFERROR(AVERAGEIF(TRADE_LOG!$H$4:$H$5003,A7,TRADE_LOG!$AG$4:$AG$5003),0) -> 1.2376238 | H7: =IFERROR(AVERAGEIFS(TRADE_LOG!$AG$4:$AG$5003,TRADE_LOG!$H$4:$H$5003,A7,TRADE_LOG!$AH$4:$AH$5003,"Win"),0) -> 1.2376238 | I7: =IFERROR(AVERAGEIFS(TRADE_LOG!$AG$4:$AG$5003,TRADE_LOG!$H$4:$H$5003,A7,TRADE_LOG!$AH$4:$AH$5003,"Loss"),0) -> 0 | J7: =IFERROR(maxifs(TRADE_LOG!$AG$4:$AG$5003,TRADE_LOG!$H$4:$H$5003,A7),0) -> 0 | K7: =IFERROR(minifs(TRADE_LOG!$AG$4:$AG$5003,TRADE_LOG!$H$4:$H$5003,A7),0) -> 0 | L7: =IFERROR(SUMIF(TRADE_LOG!$H$4:$H$5003,A7,TRADE_LOG!$AE$4:$AE$5003),0) -> 618.81188 | M7: =IFERROR(L7/B7,0) -> 618.81188 | N7: =IFERROR(F7*H7+(1-F7)*I7,0) -> 1.2376238 | O7: =IFERROR((C7*H7)/(D7*ABS(I7)),0) -> 0
A8: Scalp | B8: =COUNTIF(TRADE_LOG!$H$4:$H$5003,A8) -> 0 | C8: =COUNTIFS(TRADE_LOG!$H$4:$H$5003,A8,TRADE_LOG!$AH$4:$AH$5003,"Win") -> 0 | D8: =COUNTIFS(TRADE_LOG!$H$4:$H$5003,A8,TRADE_LOG!$AH$4:$AH$5003,"Loss") -> 0 | E8: =COUNTIFS(TRADE_LOG!$H$4:$H$5003,A8,TRADE_LOG!$AH$4:$AH$5003,"Breakeven") -> 0 | F8: =IFERROR(C8/B8,0) -> 0 | G8: =IFERROR(AVERAGEIF(TRADE_LOG!$H$4:$H$5003,A8,TRADE_LOG!$AG$4:$AG$5003),0) -> 0 | H8: =IFERROR(AVERAGEIFS(TRADE_LOG!$AG$4:$AG$5003,TRADE_LOG!$H$4:$H$5003,A8,TRADE_LOG!$AH$4:$AH$5003,"Win"),0) -> 0 | I8: =IFERROR(AVERAGEIFS(TRADE_LOG!$AG$4:$AG$5003,TRADE_LOG!$H$4:$H$5003,A8,TRADE_LOG!$AH$4:$AH$5003,"Loss"),0) -> 0 | J8: =IFERROR(maxifs(TRADE_LOG!$AG$4:$AG$5003,TRADE_LOG!$H$4:$H$5003,A8),0) -> 0 | K8: =IFERROR(minifs(TRADE_LOG!$AG$4:$AG$5003,TRADE_LOG!$H$4:$H$5003,A8),0) -> 0 | L8: =IFERROR(SUMIF(TRADE_LOG!$H$4:$H$5003,A8,TRADE_LOG!$AE$4:$AE$5003),0) -> 0 | M8: =IFERROR(L8/B8,0) -> 0 | N8: =IFERROR(F8*H8+(1-F8)*I8,0) -> 0 | O8: =IFERROR((C8*H8)/(D8*ABS(I8)),0) -> 0
A9: News Trade | B9: =COUNTIF(TRADE_LOG!$H$4:$H$5003,A9) -> 0 | C9: =COUNTIFS(TRADE_LOG!$H$4:$H$5003,A9,TRADE_LOG!$AH$4:$AH$5003,"Win") -> 0 | D9: =COUNTIFS(TRADE_LOG!$H$4:$H$5003,A9,TRADE_LOG!$AH$4:$AH$5003,"Loss") -> 0 | E9: =COUNTIFS(TRADE_LOG!$H$4:$H$5003,A9,TRADE_LOG!$AH$4:$AH$5003,"Breakeven") -> 0 | F9: =IFERROR(C9/B9,0) -> 0 | G9: =IFERROR(AVERAGEIF(TRADE_LOG!$H$4:$H$5003,A9,TRADE_LOG!$AG$4:$AG$5003),0) -> 0 | H9: =IFERROR(AVERAGEIFS(TRADE_LOG!$AG$4:$AG$5003,TRADE_LOG!$H$4:$H$5003,A9,TRADE_LOG!$AH$4:$AH$5003,"Win"),0) -> 0 | I9: =IFERROR(AVERAGEIFS(TRADE_LOG!$AG$4:$AG$5003,TRADE_LOG!$H$4:$H$5003,A9,TRADE_LOG!$AH$4:$AH$5003,"Loss"),0) -> 0 | J9: =IFERROR(maxifs(TRADE_LOG!$AG$4:$AG$5003,TRADE_LOG!$H$4:$H$5003,A9),0) -> 0 | K9: =IFERROR(minifs(TRADE_LOG!$AG$4:$AG$5003,TRADE_LOG!$H$4:$H$5003,A9),0) -> 0 | L9: =IFERROR(SUMIF(TRADE_LOG!$H$4:$H$5003,A9,TRADE_LOG!$AE$4:$AE$5003),0) -> 0 | M9: =IFERROR(L9/B9,0) -> 0 | N9: =IFERROR(F9*H9+(1-F9)*I9,0) -> 0 | O9: =IFERROR((C9*H9)/(D9*ABS(I9)),0) -> 0
A10: Support/Resistance | B10: =COUNTIF(TRADE_LOG!$H$4:$H$5003,A10) -> 0 | C10: =COUNTIFS(TRADE_LOG!$H$4:$H$5003,A10,TRADE_LOG!$AH$4:$AH$5003,"Win") -> 0 | D10: =COUNTIFS(TRADE_LOG!$H$4:$H$5003,A10,TRADE_LOG!$AH$4:$AH$5003,"Loss") -> 0 | E10: =COUNTIFS(TRADE_LOG!$H$4:$H$5003,A10,TRADE_LOG!$AH$4:$AH$5003,"Breakeven") -> 0 | F10: =IFERROR(C10/B10,0) -> 0 | G10: =IFERROR(AVERAGEIF(TRADE_LOG!$H$4:$H$5003,A10,TRADE_LOG!$AG$4:$AG$5003),0) -> 0 | H10: =IFERROR(AVERAGEIFS(TRADE_LOG!$AG$4:$AG$5003,TRADE_LOG!$H$4:$H$5003,A10,TRADE_LOG!$AH$4:$AH$5003,"Win"),0) -> 0 | I10: =IFERROR(AVERAGEIFS(TRADE_LOG!$AG$4:$AG$5003,TRADE_LOG!$H$4:$H$5003,A10,TRADE_LOG!$AH$4:$AH$5003,"Loss"),0) -> 0 | J10: =IFERROR(maxifs(TRADE_LOG!$AG$4:$AG$5003,TRADE_LOG!$H$4:$H$5003,A10),0) -> 0 | K10: =IFERROR(minifs(TRADE_LOG!$AG$4:$AG$5003,TRADE_LOG!$H$4:$H$5003,A10),0) -> 0 | L10: =IFERROR(SUMIF(TRADE_LOG!$H$4:$H$5003,A10,TRADE_LOG!$AE$4:$AE$5003),0) -> 0 | M10: =IFERROR(L10/B10,0) -> 0 | N10: =IFERROR(F10*H10+(1-F10)*I10,0) -> 0 | O10: =IFERROR((C10*H10)/(D10*ABS(I10)),0) -> 0
A11: ICT/SMC | B11: =COUNTIF(TRADE_LOG!$H$4:$H$5003,A11) -> 1 | C11: =COUNTIFS(TRADE_LOG!$H$4:$H$5003,A11,TRADE_LOG!$AH$4:$AH$5003,"Win") -> 1 | D11: =COUNTIFS(TRADE_LOG!$H$4:$H$5003,A11,TRADE_LOG!$AH$4:$AH$5003,"Loss") -> 0 | E11: =COUNTIFS(TRADE_LOG!$H$4:$H$5003,A11,TRADE_LOG!$AH$4:$AH$5003,"Breakeven") -> 0 | F11: =IFERROR(C11/B11,0) -> 1 | G11: =IFERROR(AVERAGEIF(TRADE_LOG!$H$4:$H$5003,A11,TRADE_LOG!$AG$4:$AG$5003),0) -> 1.5 | H11: =IFERROR(AVERAGEIFS(TRADE_LOG!$AG$4:$AG$5003,TRADE_LOG!$H$4:$H$5003,A11,TRADE_LOG!$AH$4:$AH$5003,"Win"),0) -> 1.5 | I11: =IFERROR(AVERAGEIFS(TRADE_LOG!$AG$4:$AG$5003,TRADE_LOG!$H$4:$H$5003,A11,TRADE_LOG!$AH$4:$AH$5003,"Loss"),0) -> 0 | J11: =IFERROR(maxifs(TRADE_LOG!$AG$4:$AG$5003,TRADE_LOG!$H$4:$H$5003,A11),0) -> 0 | K11: =IFERROR(minifs(TRADE_LOG!$AG$4:$AG$5003,TRADE_LOG!$H$4:$H$5003,A11),0) -> 0 | L11: =IFERROR(SUMIF(TRADE_LOG!$H$4:$H$5003,A11,TRADE_LOG!$AE$4:$AE$5003),0) -> 750 | M11: =IFERROR(L11/B11,0) -> 750 | N11: =IFERROR(F11*H11+(1-F11)*I11,0) -> 1.5 | O11: =IFERROR((C11*H11)/(D11*ABS(I11)),0) -> 0
A12: Price Action | B12: =COUNTIF(TRADE_LOG!$H$4:$H$5003,A12) -> 1 | C12: =COUNTIFS(TRADE_LOG!$H$4:$H$5003,A12,TRADE_LOG!$AH$4:$AH$5003,"Win") -> 1 | D12: =COUNTIFS(TRADE_LOG!$H$4:$H$5003,A12,TRADE_LOG!$AH$4:$AH$5003,"Loss") -> 0 | E12: =COUNTIFS(TRADE_LOG!$H$4:$H$5003,A12,TRADE_LOG!$AH$4:$AH$5003,"Breakeven") -> 0 | F12: =IFERROR(C12/B12,0) -> 1 | G12: =IFERROR(AVERAGEIF(TRADE_LOG!$H$4:$H$5003,A12,TRADE_LOG!$AG$4:$AG$5003),0) -> 1.8333333 | H12: =IFERROR(AVERAGEIFS(TRADE_LOG!$AG$4:$AG$5003,TRADE_LOG!$H$4:$H$5003,A12,TRADE_LOG!$AH$4:$AH$5003,"Win"),0) -> 1.8333333 | I12: =IFERROR(AVERAGEIFS(TRADE_LOG!$AG$4:$AG$5003,TRADE_LOG!$H$4:$H$5003,A12,TRADE_LOG!$AH$4:$AH$5003,"Loss"),0) -> 0 | J12: =IFERROR(maxifs(TRADE_LOG!$AG$4:$AG$5003,TRADE_LOG!$H$4:$H$5003,A12),0) -> 0 | K12: =IFERROR(minifs(TRADE_LOG!$AG$4:$AG$5003,TRADE_LOG!$H$4:$H$5003,A12),0) -> 0 | L12: =IFERROR(SUMIF(TRADE_LOG!$H$4:$H$5003,A12,TRADE_LOG!$AE$4:$AE$5003),0) -> 916.66667 | M12: =IFERROR(L12/B12,0) -> 916.66667 | N12: =IFERROR(F12*H12+(1-F12)*I12,0) -> 1.8333333 | O12: =IFERROR((C12*H12)/(D12*ABS(I12)),0) -> 0
A13: Harmonic | B13: =COUNTIF(TRADE_LOG!$H$4:$H$5003,A13) -> 0 | C13: =COUNTIFS(TRADE_LOG!$H$4:$H$5003,A13,TRADE_LOG!$AH$4:$AH$5003,"Win") -> 0 | D13: =COUNTIFS(TRADE_LOG!$H$4:$H$5003,A13,TRADE_LOG!$AH$4:$AH$5003,"Loss") -> 0 | E13: =COUNTIFS(TRADE_LOG!$H$4:$H$5003,A13,TRADE_LOG!$AH$4:$AH$5003,"Breakeven") -> 0 | F13: =IFERROR(C13/B13,0) -> 0 | G13: =IFERROR(AVERAGEIF(TRADE_LOG!$H$4:$H$5003,A13,TRADE_LOG!$AG$4:$AG$5003),0) -> 0 | H13: =IFERROR(AVERAGEIFS(TRADE_LOG!$AG$4:$AG$5003,TRADE_LOG!$H$4:$H$5003,A13,TRADE_LOG!$AH$4:$AH$5003,"Win"),0) -> 0 | I13: =IFERROR(AVERAGEIFS(TRADE_LOG!$AG$4:$AG$5003,TRADE_LOG!$H$4:$H$5003,A13,TRADE_LOG!$AH$4:$AH$5003,"Loss"),0) -> 0 | J13: =IFERROR(maxifs(TRADE_LOG!$AG$4:$AG$5003,TRADE_LOG!$H$4:$H$5003,A13),0) -> 0 | K13: =IFERROR(minifs(TRADE_LOG!$AG$4:$AG$5003,TRADE_LOG!$H$4:$H$5003,A13),0) -> 0 | L13: =IFERROR(SUMIF(TRADE_LOG!$H$4:$H$5003,A13,TRADE_LOG!$AE$4:$AE$5003),0) -> 0 | M13: =IFERROR(L13/B13,0) -> 0 | N13: =IFERROR(F13*H13+(1-F13)*I13,0) -> 0 | O13: =IFERROR((C13*H13)/(D13*ABS(I13)),0) -> 0
